Workbook
Name _bgvbyrgdt: [1]Tidsserier!$A$339:$IV$339
Name _bgvbyrlpg: [1]Tidsserier!$A$337:$IV$337
Name _bgvbyrlvn: [1]Tidsserier!$A$338:$IV$338
Name _bgvbyrnga: [1]Tidsserier!$A$340:$IV$340
Name _bgvbyrrga: [1]Tidsserier!$A$336:$IV$336
Name _bgvbyrska: [1]Tidsserier!$A$341:$IV$341
Name _celelrfut: [1]Tidsserier!$A$174:$IV$174
Name _celelrgdt: [1]Tidsserier!$A$173:$IV$173
Name _celelrhal: [1]Tidsserier!$A$176:$IV$176
Name _celelrske: [1]Tidsserier!$A$175:$IV$175
Name _cevelraff: [1]Tidsserier!$A$197:$IV$197
Name _cevelrbio: [1]Tidsserier!$A$196:$IV$196
Name _cevelrfli: [1]Tidsserier!$A$193:$IV$193
Name _cevelrfut: [1]Tidsserier!$A$187:$IV$187
Name _cevelrgdt: [1]Tidsserier!$A$186:$IV$186
Name _cevelrhal: [1]Tidsserier!$A$192:$IV$192
Name _cevelrlpg: [1]Tidsserier!$A$184:$IV$184
Name _cevelrlvn: [1]Tidsserier!$A$185:$IV$185
Name _cevelrnga: [1]Tidsserier!$A$190:$IV$190
Name _cevelrori: [1]Tidsserier!$A$189:$IV$189
Name _cevelrpko: [1]Tidsserier!$A$188:$IV$188
Name _cevelrrga: [1]Tidsserier!$A$183:$IV$183
Name _cevelrske: [1]Tidsserier!$A$191:$IV$191
Name _cevelrtaf: [1]Tidsserier!$A$195:$IV$195
Name _cevfjraff: [1]Tidsserier!$A$213:$IV$213
Name _cevfjrbio: [1]Tidsserier!$A$212:$IV$212
Name _cevfjrfli: [1]Tidsserier!$A$209:$IV$209
Name _cevfjrfut: [1]Tidsserier!$A$203:$IV$203
Name _cevfjrgdt: [1]Tidsserier!$A$202:$IV$202
Name _cevfjrhal: [1]Tidsserier!$A$208:$IV$208
Name _cevfjrlpg: [1]Tidsserier!$A$200:$IV$200
Name _cevfjrlvn: [1]Tidsserier!$A$201:$IV$201
Name _cevfjrnga: [1]Tidsserier!$A$206:$IV$206
Name _cevfjrori: [1]Tidsserier!$A$205:$IV$205
Name _cevfjrpko: [1]Tidsserier!$A$204:$IV$204
Name _cevfjrrga: [1]Tidsserier!$A$199:$IV$199
Name _cevfjrske: [1]Tidsserier!$A$207:$IV$207
Name _cevfjrtaf: [1]Tidsserier!$A$211:$IV$211
Name _cevfjrtpi: [1]Tidsserier!$A$210:$IV$210
Name _dnkexpelc: [1]Tidsserier!$A$69:$IV$69
Name _dnkexpnga: [1]Tidsserier!$A$68:$IV$68
Name _dnkexprao: [1]Tidsserier!$A$52:$IV$52
Name _dnkimpelc: [1]Tidsserier!$A$45:$IV$45
Name _dnkimpfjv: [1]Tidsserier!$A$46:$IV$46
Name _dnkudvaff: [1]Tidsserier!$A$17:$IV$17
Name _dnkudvbio: [1]Tidsserier!$A$16:$IV$16
Name _dnkudvbra: [1]Tidsserier!$A$13:$IV$13
Name _dnkudvfio: [1]Tidsserier!$A$18:$IV$18
Name _dnkudvfli: [1]Tidsserier!$A$12:$IV$12
Name _dnkudvgeo: [1]Tidsserier!$A$10:$IV$10
Name _dnkudvhal: [1]Tidsserier!$A$11:$IV$11
Name _dnkudvsol: [1]Tidsserier!$A$7:$IV$7
Name _dnkudvtaf: [1]Tidsserier!$A$15:$IV$15
Name _dnkudvtpi: [1]Tidsserier!$A$14:$IV$14
Name _dnkudvvan: [1]Tidsserier!$A$9:$IV$9
Name _dnkudvvin: [1]Tidsserier!$A$8:$IV$8
Name _dnkudvvmp: [1]Tidsserier!$A$19:$IV$19
Name _ensdstelc: [1]Tidsserier!$A$348:$IV$348
Name _enstabfjv: [1]Tidsserier!$A$352:$IV$352
Name _enstabnga: [1]Tidsserier!$A$350:$IV$350

Sheet LOG
A1: Selects cells and the then Ctrl+shift+L to add entries
A3: Date | B3: Name | C3: Sheet Name | D3: Cell no
A4: 44297 | B4: Mikkel Bosack Simonsen | C4: All | E4: Based on the ONTIMES model a structure has been developed for the TIMES-AZ model.
A5: 44298 | B5: Mikkel Bosack Simonsen | C5: All | E5: Removed all Norwegian dataset and implemented Azabaijanian energy statistics, allthough service demand split is used based on WMAS study in Denmark. Expected to be changed for heavy industri

Sheet Intro
B1: Description
B3: Purpose: | C3: This sheet defines processes, commodities and existing stocks for industies energy services
B4: Description: | C4: The data is based on the VMAS survey of energy services as well as the energy matrices from Statistics Denmark
B6: Relevant sectors | C6: IND
B8: Description of different sheets
B10: Processes | C10: Defines the processes for each sector
B11: Commodities | C11: Defines the commodities used in the processes
B12: Demand | C12: Benchmark demand for energy services for all industries 2010
B13: IronSteel | C13: Topology for processes and commodities used in Agriculture
B14: Chemical | C14: Topology for processes and commodities used in Food
B15: Aluminium | C15: Topology for processes and commodities used in Chemical
B16: GlassConcrete | C16: Topology for processes and commodities used in Glass&Concrete
B17: Transport | C17: Topology for processes and commodities used in Metal
B18: Machinery | C18: Topology for processes and commodities used in Other
B19: Mining | C19: Topology for processes and commodities used in Motor Vehicles
B20: Food | C20: Topology for processes and commodities used in Sales
B21: PulpPaper | C21: Topology for processes and commodities used in PrivateServices
... B28: Energy Matrix | C28: Energy matrix from Statistics Denmark 2010
B29: 2010 | C29: =B29&" Energy statistics of Azerbaijan" -> 2010 Energy statistics of Azerbaijan
B30: 2015 | C30: =B30&" Energy statistics of Azerbaijan" -> 2015 Energy statistics of Azerbaijan
B31: 2019 | C31: =B31&" Energy statistics of Azerbaijan" -> 2019 Energy statistics of Azerbaijan

Sheet Processes
B4: ~FI_Process | R4: Text to associate with Tech Names:
B5: Sets | C5: Region | D5: TechName | E5: TechDesc | F5: Tact | G5: Tcap | H5: Tslvl | I5: PrimaryCG | J5: Vintage | R5: - and in column R a one letter code to be used in Tech Name.
B6: *Process Set Membership | C6: Region Name | D6: Technology Name | E6: Technology Description | F6: Activity Unit | G6: Capacity Unit | H6: TimeSlice level of Process Activity | I6: Primary Commodity Group | J6: Vintage Tracking | O6: Comm-IN | P6: Comm-OUT | R6: This colour: Input
B7: DMD | D7: =M13 & P$7 & R$7 & VLOOKUP(O$7, $O$50:$P$75,2,FALSE) & "E1" -> AGRPHBNGAE1 | E7: =+M10 & " " & S$7 & " - " & T$7 & " " & U$7 -> Agriculture Heat Medium Temp. Boiler - Nat. Gas Existing 1 | F7: PJ | G7: MW | L7: Index: 1 - 9 | M7: 1 | O7: =Commodities!$D$29&","&Commodities!$D$30&","&Commodities!$D$13 -> AGRSNG1,AGRSNG2,AGRNGA | P7: =+Commodities!$AL$6 -> PH | R7: B | S7: Heat Medium Temp. Boiler | T7: Nat. Gas | U7: Existing 1
B8: =+IF(ISBLANK(D8),"*","") | D8: =M13 & P$8 & R$8 & VLOOKUP(O$8, $O$50:$P$75,2,FALSE) & "E1" -> AGRPHBCOAE1 | E8: =+M10 & " " & S$8 & " - " & T$8 & " " & U$8 -> Agriculture Heat Medium Temp. Boiler - Coal Existing 1 | F8: PJ | G8: MW | O8: =Commodities!$D$14 -> AGRCOA | P8: =+Commodities!$AL$6 -> PH | R8: =+R$7 -> B | S8: =+S$7 -> Heat Medium Temp. Boiler | T8: Coal | U8: =+U$7 -> Existing 1
B9: =+IF(ISBLANK(D9),"*","") | D9: =M13 & P$9 & R$9 & VLOOKUP(O$9, $O$50:$P$75,2,FALSE) & "E1" -> AGRPHBDSLE1 | E9: =+M10 & " " & S$9 & " - " & T$9 & " " & U$9 -> Agriculture Heat Medium Temp. Boiler - Diesel Existing 1 | F9: PJ | G9: MW | L9: Sheet: | M9: Commodities | O9: =Commodities!$D$27&","&Commodities!$D$28&","&Commodities!$D$15 -> AGRDSB1,AGRDSB2,AGRDSL | P9: =+Commodities!$AL$6 -> PH | R9: =+R$7 -> B | S9: =+S$7 -> Heat Medium Temp. Boiler | T9: Diesel | U9: =+U$7 -> Existing 1
B10: =+IF(ISBLANK(D10),"*","") | D10: =M13 & P$10 & R$10 & VLOOKUP(O$10, $O$50:$P$75,2,FALSE) & "E1" -> AGRPHBWPEE1 | E10: =+M10 & " " & S$10 & " - " & T$10 & " " & U$10 -> Agriculture Heat Medium Temp. Boiler - Wood Pellets Existing 1 | F10: PJ | G10: MW | L10: Sector: | M10: =+INDEX(Commodities!$X$6:$X$6,M7) -> Agriculture | O10: =Commodities!$D$16 -> AGRWPE | P10: =+Commodities!$AL$6 -> PH | R10: =+R$7 -> B | S10: =+S$7 -> Heat Medium Temp. Boiler | T10: Wood Pellets | U10: =+U$7 -> Existing 1
B11: =+IF(ISBLANK(D11),"*","") -> * | M11: =+INDEX(Commodities!$Y$6:$Y$6,M7) -> Agriculture, forestry and fishing | O11: =Commodities!$D$17 -> AGRWCH
B12: =+IF(ISBLANK(D12),"*","") | D12: =M13 & P$12 & R$12 & VLOOKUP(O$12, $O$50:$P$75,2,FALSE) & "E1" -> AGRPHBBGAE1 | E12: =+M10 & " " & S$12 & " - " & T$12 & " " & U$12 -> Agriculture Heat Medium Temp. Boiler - Biogas Existing 1 | F12: PJ | G12: MW | L12: Code: | M12: =+INDEX(Commodities!$U$6:$U$6,M7) -> AG | O12: =Commodities!$D$18 -> AGRBGA | P12: =+Commodities!$AL$6 -> PH | R12: =+R$7 -> B | S12: =+S$7 -> Heat Medium Temp. Boiler | T12: Biogas | U12: =+U$7 -> Existing 1
B13: =+IF(ISBLANK(D13),"*","") | D13: =M13 & P$13 & R$13 & VLOOKUP(O$13, $O$50:$P$75,2,FALSE) & "E1" -> AGRPHBHFOE1 | E13: =+M10 & " " & S$13 & " - " & T$13 & " " & U$13 -> Agriculture Heat Medium Temp. Boiler - Heavy Fuel Oil Existing 1 | F13: PJ | G13: MW | L13: Code: | M13: =+INDEX(Commodities!$W$6:$W$6,M7) -> AGR | O13: =Commodities!$D$19 -> AGRHFO | P13: =+Commodities!$AL$6 -> PH | R13: =+R$7 -> B | S13: =+S$7 -> Heat Medium Temp. Boiler | T13: Heavy Fuel Oil | U13: =+U$7 -> Existing 1
B14: =+IF(ISBLANK(D14),"*","") | D14: =M13 & P$14 & R$14 & VLOOKUP(O$14, $O$50:$P$75,2,FALSE) & "E1" -> AGRPHBLPGE1 | E14: =+M10 & " " & S$14 & " - " & T$14 & " " & U$14 -> Agriculture Heat Medium Temp. Boiler - Liquified Petroleum Gas Existing 1 | F14: PJ | G14: MW | O14: =Commodities!$D$20 -> AGRLPG | P14: =+Commodities!$AL$6 -> PH | R14: =+R$7 -> B | S14: =+S$7 -> Heat Medium Temp. Boiler | T14: Liquified Petroleum Gas | U14: =+U$7 -> Existing 1
B15: =+IF(ISBLANK(D15),"*","") | D15: =M13 & P$15 & R$15 & VLOOKUP(O$15, $O$50:$P$75,2,FALSE) & "E1" -> AGRPHBWSTE1 | E15: =+M10 & " " & S$15 & " - " & T$15 & " " & U$15 -> Agriculture Heat Medium Temp. Boiler - Waste Existing 1 | F15: PJ | G15: MW | O15: =Commodities!$D$21 -> AGRWST | P15: =+Commodities!$AL$6 -> PH | R15: =+R$7 -> B | S15: =+S$7 -> Heat Medium Temp. Boiler | T15: Waste | U15: =+U$7 -> Existing 1
B16: =+IF(ISBLANK(D16),"*","") | D16: =M13 & P$16 & R$16 & VLOOKUP(O$16, $O$50:$P$75,2,FALSE) & "E1" -> AGRPHBHETE1 | E16: =+M10 & " " & S$16 & " - " & T$16 & " " & U$16 -> Agriculture Heat Medium Temp. Boiler - Dist. Heat Existing 1 | F16: PJ | G16: MW | O16: =Commodities!$D$22 -> AGRHCE | P16: =+Commodities!$AL$6 -> PH | R16: =+R$7 -> B | S16: =+S$7 -> Heat Medium Temp. Boiler | T16: Dist. Heat | U16: =+U$7 -> Existing 1
B17: =+IF(ISBLANK(D17),"*","") -> * | O17: =Commodities!$D$24 -> AGRHDE
B18: =+IF(ISBLANK(D18),"*","") | D18: =M13 & P$18 & R$18 & VLOOKUP(O$18, $O$50:$P$75,2,FALSE) & "E1" -> AGRPHBELCE1 | E18: =+M10 & " " & S$18 & " - " & T$18 & " " & U$18 -> Agriculture Heat Medium Temp. Boiler - Electricity Existing 1 | F18: PJ | G18: MW | O18: =Commodities!$D$25 -> AGRELC | P18: =+Commodities!$AL$6 -> PH | R18: =+R$7 -> B | S18: =+S$7 -> Heat Medium Temp. Boiler | T18: Electricity | U18: =+U$7 -> Existing 1
B19: =+IF(ISBLANK(D19),"*","") | D19: =M13 & P$19 & R$19 & VLOOKUP(O$19, $O$50:$P$75,2,FALSE) & "E1" -> AGRCOBNGAE1 | E19: =+M10 & " " & S$19 & " - " & T$19 & " " & U$19 -> Agriculture Heat High Temp. Boiler - Nat. Gas Existing 1 | F19: PJ | G19: MW | O19: =Commodities!$D$29&","&Commodities!$D$30&","&Commodities!$D$13 -> AGRSNG1,AGRSNG2,AGRNGA | P19: =+Commodities!$AL$7 -> CO | R19: =+R$7 -> B | S19: Heat High Temp. Boiler | T19: =+T$7 -> Nat. Gas | U19: =+U$7 -> Existing 1
B20: =+IF(ISBLANK(D20),"*","") | D20: =M13 & P$20 & R$20 & VLOOKUP(O$20, $O$50:$P$75,2,FALSE) & "E1" -> AGRCOBCOAE1 | E20: =+M10 & " " & S$20 & " - " & T$20 & " " & U$20 -> Agriculture Heat High Temp. Boiler - Coal Existing 1 | F20: PJ | G20: MW | O20: =Commodities!$D$14 -> AGRCOA | P20: =+Commodities!$AL$7 -> CO | R20: =+R$7 -> B | S20: =$S$19 -> Heat High Temp. Boiler | T20: Coal | U20: =+U$7 -> Existing 1
B21: =+IF(ISBLANK(D21),"*","") | D21: =M13 & P$21 & R$21 & VLOOKUP(O$21, $O$50:$P$75,2,FALSE) & "E1" -> AGRCOBDSLE1 | E21: =+M10 & " " & S$21 & " - " & T$21 & " " & U$21 -> Agriculture Heat High Temp. Boiler - Diesel Existing 1 | F21: PJ | G21: MW | O21: =Commodities!$D$27&","&Commodities!$D$28&","&Commodities!$D$15 -> AGRDSB1,AGRDSB2,AGRDSL | P21: =+Commodities!$AL$7 -> CO | R21: =+R$7 -> B | S21: =$S$19 -> Heat High Temp. Boiler | T21: Diesel | U21: =+U$7 -> Existing 1
B22: =+IF(ISBLANK(D22),"*","") | D22: =M13 & P$22 & R$22 & VLOOKUP(O$22, $O$50:$P$75,2,FALSE) & "E1" -> AGRCOBWPEE1 | E22: =+M10 & " " & S$22 & " - " & T$22 & " " & U$22 -> Agriculture Heat High Temp. Boiler - Wood Pellets Existing 1 | F22: PJ | G22: MW | O22: =Commodities!$D$16 -> AGRWPE | P22: =+Commodities!$AL$7 -> CO | R22: =+R$7 -> B | S22: =$S$19 -> Heat High Temp. Boiler | T22: Wood Pellets | U22: =+U$7 -> Existing 1
B23: =+IF(ISBLANK(D23),"*","") -> * | O23: =Commodities!$D$17 -> AGRWCH
B24: =+IF(ISBLANK(D24),"*","") | D24: =M13 & P$24 & R$24 & VLOOKUP(O$24, $O$50:$P$75,2,FALSE) & "E1" -> AGRCOBHFOE1 | E24: =+M10 & " " & S$24 & " - " & T$24 & " " & U$24 -> Agriculture Heat High Temp. Boiler - Heavy Fuel Oil Existing 1 | F24: PJ | G24: MW | O24: =Commodities!$D$19 -> AGRHFO | P24: =+Commodities!$AL$7 -> CO | R24: =+R$7 -> B | S24: =$S$19 -> Heat High Temp. Boiler | T24: Heavy Fuel Oil | U24: =+U$7 -> Existing 1
B25: =+IF(ISBLANK(D25),"*","") | D25: =M13 & P$25 & R$25 & VLOOKUP(O$25, $O$50:$P$75,2,FALSE) & "E1" -> AGRCOBLPGE1 | E25: =+M10 & " " & S$25 & " - " & T$25 & " " & U$25 -> Agriculture Heat High Temp. Boiler - Liquified Petroleum Gas Existing 1 | F25: PJ | G25: MW | O25: =Commodities!$D$20 -> AGRLPG | P25: =+Commodities!$AL$7 -> CO | R25: =+R$7 -> B | S25: =$S$19 -> Heat High Temp. Boiler | T25: Liquified Petroleum Gas | U25: =+U$7 -> Existing 1
B26: =+IF(ISBLANK(D26),"*","") | D26: =M13 & P$26 & R$26 & VLOOKUP(O$26, $O$50:$P$75,2,FALSE) & "E1" -> AGRCOBWSTE1 | E26: =+M10 & " " & S$26 & " - " & T$26 & " " & U$26 -> Agriculture Heat High Temp. Boiler - Waste Existing 1 | F26: PJ | G26: MW | O26: =Commodities!$D$21 -> AGRWST | P26: =+Commodities!$AL$7 -> CO | R26: =+R$7 -> B | S26: =$S$19 -> Heat High Temp. Boiler | T26: Waste | U26: Existing 1
B27: =+IF(ISBLANK(D27),"*","") | D27: =M13 & P$27 & R$27 & VLOOKUP(O$27, $O$50:$P$75,2,FALSE) & "E1" -> AGRCOBELCE1 | E27: =+M10 & " " & S$27 & " - " & T$27 & " " & U$27 -> Agriculture Heat High Temp. Boiler - Electricity Existing 1 | F27: PJ | G27: MW | O27: =Commodities!$D$25 -> AGRELC | P27: =+Commodities!$AL$7 -> CO | R27: =+R$7 -> B | S27: =$S$19 -> Heat High Temp. Boiler | T27: Electricity | U27: Existing 1
B28: =+IF(ISBLANK(D28),"*","") | D28: =M13 & P$28 & R$28 & VLOOKUP(O$28, $O$50:$P$75,2,FALSE) & "E1" -> AGRSHBNGAE1 | E28: =+M10 & " " & S$28 & " - " & T$28 & " " & U$28 -> Agriculture Heat Room Boiler - Nat. Gas Existing 1 | F28: PJ | G28: MW | O28: =Commodities!$D$29&","&Commodities!$D$30&","&Commodities!$D$13 -> AGRSNG1,AGRSNG2,AGRNGA | P28: =+Commodities!$AL$8 -> SH | R28: =+R$7 -> B | S28: Heat Room Boiler | T28: =+T7 -> Nat. Gas | U28: =+U$7 -> Existing 1
B29: =+IF(ISBLANK(D29),"*","") | D29: =M13 & P$29 & R$29 & VLOOKUP(O$29, $O$50:$P$75,2,FALSE) & "E1" -> AGRSHBCOAE1 | E29: =+M10 & " " & S$29 & " - " & T$29 & " " & U$29 -> Agriculture Heat Room Boiler - Coal Existing 1 | F29: PJ | G29: MW | O29: =Commodities!$D$14 -> AGRCOA | P29: =+Commodities!$AL$8 -> SH | R29: =+R$7 -> B | S29: =+S$28 -> Heat Room Boiler | T29: =+T8 -> Coal | U29: =+U$7 -> Existing 1
B30: =+IF(ISBLANK(D30),"*","") | D30: =M13 & P$30 & R$30 & VLOOKUP(O$30, $O$50:$P$75,2,FALSE) & "E1" -> AGRSHBDSLE1 | E30: =+M10 & " " & S$30 & " - " & T$30 & " " & U$30 -> Agriculture Heat Room Boiler - Diesel Existing 1 | F30: PJ | G30: MW | O30: =Commodities!$D$27&","&Commodities!$D$28&","&Commodities!$D$15 -> AGRDSB1,AGRDSB2,AGRDSL | P30: =+Commodities!$AL$8 -> SH | R30: =+R$7 -> B | S30: =+S$28 -> Heat Room Boiler | T30: =+T9 -> Diesel | U30: =+U$7 -> Existing 1
B31: =+IF(ISBLANK(D31),"*","") | D31: =M13 & P$31 & R$31 & VLOOKUP(O$31, $O$50:$P$75,2,FALSE) & "E1" -> AGRSHBWPEE1 | E31: =+M10 & " " & S$31 & " - " & T$31 & " " & U$31 -> Agriculture Heat Room Boiler - Wood Pellets Existing 1 | F31: PJ | G31: MW | O31: =Commodities!$D$16 -> AGRWPE | P31: =+Commodities!$AL$8 -> SH | R31: =+R$7 -> B | S31: =+S$28 -> Heat Room Boiler | T31: =+T10 -> Wood Pellets | U31: =+U$7 -> Existing 1
B32: =+IF(ISBLANK(D32),"*","") -> * | O32: =Commodities!$D$17 -> AGRWCH
B33: =+IF(ISBLANK(D33),"*","") | D33: =M13 & P$33 & R$33 & VLOOKUP(O$33, $O$50:$P$75,2,FALSE) & "E1" -> AGRSHBBGAE1 | E33: =+M10 & " " & S$33 & " - " & T$33 & " " & U$33 -> Agriculture Heat Room Boiler - Biogas Existing 1 | F33: PJ | G33: MW | O33: =Commodities!$D$18 -> AGRBGA | P33: =+Commodities!$AL$8 -> SH | R33: =+R$7 -> B | S33: =+S$28 -> Heat Room Boiler | T33: =+T12 -> Biogas | U33: =+U$7 -> Existing 1
B34: =+IF(ISBLANK(D34),"*","") | D34: =M13 & P$34 & R$34 & VLOOKUP(O$34, $O$50:$P$75,2,FALSE) & "E1" -> AGRSHBHFOE1 | E34: =+M10 & " " & S$34 & " - " & T$34 & " " & U$34 -> Agriculture Heat Room Boiler - Heavy Fuel Oil Existing 1 | F34: PJ | G34: MW | O34: =Commodities!$D$19 -> AGRHFO | P34: =+Commodities!$AL$8 -> SH | R34: =+R$7 -> B | S34: =+S$28 -> Heat Room Boiler | T34: =+T13 -> Heavy Fuel Oil | U34: =+U$7 -> Existing 1
B35: =+IF(ISBLANK(D35),"*","") | D35: =M13 & P$35 & R$35 & VLOOKUP(O$35, $O$50:$P$75,2,FALSE) & "E1" -> AGRSHBLPGE1 | E35: =+M10 & " " & S$35 & " - " & T$35 & " " & U$35 -> Agriculture Heat Room Boiler - Liquified Petroleum Gas Existing 1 | F35: PJ | G35: MW | O35: =Commodities!$D$20 -> AGRLPG | P35: =+Commodities!$AL$8 -> SH | R35: =+R$7 -> B | S35: =+S$28 -> Heat Room Boiler | T35: =+T14 -> Liquified Petroleum Gas | U35: =+U$7 -> Existing 1
B36: =+IF(ISBLANK(D36),"*","") | D36: =M13 & P$36 & R$36 & VLOOKUP(O$36, $O$50:$P$75,2,FALSE) & "E1" -> AGRSHBWSTE1 | E36: =+M10 & " " & S$36 & " - " & T$36 & " " & U$36 -> Agriculture Heat Room Boiler - Waste Existing 1 | F36: PJ | G36: MW | O36: =Commodities!$D$21 -> AGRWST | P36: =+Commodities!$AL$8 -> SH | R36: =+R$7 -> B | S36: =+S$28 -> Heat Room Boiler | T36: =+T15 -> Waste | U36: =+U$7 -> Existing 1
B37: =+IF(ISBLANK(D37),"*","") | D37: =M13 & P$37 & R$37 & VLOOKUP(O$37, $O$50:$P$75,2,FALSE) & "E1" -> AGRSHBHETE1 | E37: =+M10 & " " & S$37 & " - " & T$37 & " " & U$37 -> Agriculture Heat Room Boiler - Dist. Heat Existing 1 | F37: PJ | G37: MW | O37: =Commodities!$D$22 -> AGRHCE | P37: =+Commodities!$AL$8 -> SH | R37: =+R$7 -> B | S37: =+S$28 -> Heat Room Boiler | T37: =+T16 -> Dist. Heat | U37: =+U$7 -> Existing 1
B38: =+IF(ISBLANK(D38),"*","") -> * | O38: =Commodities!$D$24 -> AGRHDE
B39: =+IF(ISBLANK(D39),"*","") | D39: =M13 & P$39 & R$39 & VLOOKUP(O$39, $O$50:$P$75,2,FALSE) & "E1" -> AGRSHBELCE1 | E39: =+M10 & " " & S$39 & " - " & T$39 & " " & U$39 -> Agriculture Heat Room Boiler - Electricity Existing 1 | F39: PJ | G39: MW | O39: =Commodities!$D$25 -> AGRELC | P39: =+Commodities!$AL$8 -> SH | R39: =+R$7 -> B | S39: =+S$28 -> Heat Room Boiler | T39: =+T$18 -> Electricity | U39: =+U$7 -> Existing 1
B40: =+IF(ISBLANK(D40),"*","") | D40: =M13 & P$40 & R$40 & VLOOKUP(O$40, $O$50:$P$75,2,FALSE) & "E1" -> AGRLAAELCE1 | E40: =+M10 & " " & S$40 & " - " & T$40 & " " & U$40 -> Agriculture Electricity Light Appliance - Electricity Existing 1 | F40: PJ | G40: MW | O40: =Commodities!$D$25 -> AGRELC | P40: =+Commodities!$AL$9 -> LA | R40: A | S40: Electricity Light Appliance | T40: =+T$18 -> Electricity | U40: =+U$7 -> Existing 1
B41: =+IF(ISBLANK(D41),"*","") | D41: =M13 & P$41 & R$41 & VLOOKUP(O$41, $O$50:$P$75,2,FALSE) & "E1" -> AGREMMELCE1 | E41: =+M10 & " " & S$41 & " - " & T$41 & " " & U$41 -> Agriculture Electricity Motors - Electricity Existing 1 | F41: PJ | G41: MW | O41: =Commodities!$D$25 -> AGRELC | P41: =+Commodities!$AL$10 -> EM | R41: M | S41: Electricity Motors | T41: =+T$18 -> Electricity | U41: =+U$7 -> Existing 1
B42: =+IF(ISBLANK(D42),"*","") | D42: =M13 & P$42 & R$42 & VLOOKUP(O$42, $O$50:$P$75,2,FALSE) & "E1" -> AGRTFTDSLE1 | E42: =+M10 & " " & S$42 & " - " & T$42 & " " & U$42 -> Agriculture Tractors, Trucks, Fishing boats, Forest machines - Diesel Existing 1 | F42: PJ | G42: MW | O42: =+Commodities!D27&","&Commodities!D28&","&Commodities!D15 -> AGRDSB1,AGRDSB2,AGRDSL | P42: =+Commodities!$AL$11 -> TF | R42: T | S42: Tractors, Trucks, Fishing boats, Forest machines | T42: Diesel | U42: =+U$7 -> Existing 1
B43: =+IF(ISBLANK(D43),"*","") | D43: =M13&P$43&R$43&VLOOKUP(O$43,$O$50:$P$75,2,FALSE)&"E1" -> AGRFLTLPGE1 | E43: =+M10 & " " & S$43 & " - " & T$43 & " " & U$43 -> Agriculture Forklifts - LPG Existing 1 | F43: PJ | G43: MW | O43: =+Commodities!D20&","&Commodities!D29&","&Commodities!D30 -> AGRLPG,AGRSNG1,AGRSNG2 | P43: =+Commodities!$AL$12 -> FL | R43: =+R$42 -> T | S43: Forklifts | T43: LPG | U43: =+U$7 -> Existing 1
...

Sheet Commodities
B3: ~FI_Comm
B4: CSet | C4: Region | D4: CommName | E4: CommDesc | F4: Unit | G4: LimType | H4: CTSLvl | I4: PeakTS | J4: Ctype
B5: *Commodity Set Membership | C5: Region Name | D5: Commodity Name | E5: Commodity Description | F5: Unit | G5: Sense of the Balance EQN. | H5: Timeslice Level | I5: Peak Monitoring | J5: Electricity Indicator | T5: Index | U5: Code | V5: Code | W5: Code | X5: Sector | Y5: Text | AC5: Eurostat | AD5: Temperature Distribution | AE5: Sheet Name | AJ5: Index | AK5: Txt1 | AL5: Code | AM5: Txt2
B6: DEM | D6: =+INDEX($V$6:$V$6,M6) & INDEX($AL$6:$AL$13,L6) -> AGDPH | E6: =INDEX($X$6:$X$6,M6) & " " & INDEX($AM$6:$AM$13,L6) -> Agriculture Demand Process heat | F6: PJ | L6: 1 | M6: 1 | N6: =VLOOKUP(M6, $T$6:$Y$6, 6, FALSE) -> Agriculture, forestry and fishing | T6: 1 | U6: AG | V6: AGD | W6: AGR | X6: Agriculture | Y6: Agriculture, forestry and fishing | AC6: Agriculture, forestry and fishing | AD6: Agriculture, forestry and fishing | AE6: Agriculture | AJ6: 1 | AK6: Agriculture | AL6: PH | AM6: Demand Process heat
D7: =+INDEX($V$6:$V$6,M7) & INDEX($AL$6:$AL$13,L7) -> AGDCO | E7: =INDEX($X$6:$X$6,M7) & " " & INDEX($AM$6:$AM$13,L7) -> Agriculture Demand Cooling | F7: PJ | L7: =+L6+1 -> 2 | M7: =+M6 -> 1 | AJ7: 2 | AK7: Agriculture | AL7: CO | AM7: Demand Cooling
D8: =+INDEX($V$6:$V$6,M8) & INDEX($AL$6:$AL$13,L8) -> AGDSH | E8: =INDEX($X$6:$X$6,M8) & " " & INDEX($AM$6:$AM$13,L8) -> Agriculture Demand Spatial Heat | F8: PJ | L8: =+L7+1 -> 3 | M8: =+M7 -> 1 | AJ8: 3 | AK8: Agriculture | AL8: SH | AM8: Demand Spatial Heat
D9: =+INDEX($V$6:$V$6,M9) & INDEX($AL$6:$AL$13,L9) -> AGDLA | E9: =INDEX($X$6:$X$6,M9) & " " & INDEX($AM$6:$AM$13,L9) -> Agriculture Demand Light | F9: PJ | L9: =+L8+1 -> 4 | M9: =+M8 -> 1 | AJ9: 4 | AK9: Agriculture | AL9: LA | AM9: Demand Light
D10: =+INDEX($V$6:$V$6,M10) & INDEX($AL$6:$AL$13,L10) -> AGDEM | E10: =INDEX($X$6:$X$6,M10) & " " & INDEX($AM$6:$AM$13,L10) -> Agriculture Demand Electric Motors | F10: PJ | L10: =+L9+1 -> 5 | M10: =+M9 -> 1 | AJ10: 5 | AK10: Agriculture | AL10: EM | AM10: Demand Electric Motors
D11: =+INDEX($V$6:$V$6,M11) & INDEX($AL$6:$AL$13,L11) -> AGDTF | E11: =INDEX($X$6:$X$6,M11) & " " & INDEX($AM$6:$AM$13,L11) -> Agriculture Demand Haulage Tractors, Trucks, Fishing boats, Forest machines | F11: PJ | L11: =+L10+1 -> 6 | M11: =+M10 -> 1 | AJ11: 6 | AK11: Agriculture | AL11: TF | AM11: Demand Haulage Tractors, Trucks, Fishing boats, Forest machines
D12: =+INDEX($V$6:$V$6,M12) & INDEX($AL$6:$AL$13,L12) -> AGDFL | E12: =INDEX($X$6:$X$6,M12) & " " & INDEX($AM$6:$AM$13,L12) -> Agriculture Demand Haulage Forklifts | F12: PJ | L12: =+L11+1 -> 7 | M12: =+M11 -> 1 | AJ12: 7 | AK12: Agriculture | AL12: FL | AM12: Demand Haulage Forklifts
B13: NRG,NGR-IND | D13: ="AGR"&RIGHT(L13,LEN(L13)-3) -> AGRNGA | E13: =LEFT(M13,LEN(M13)-3)&" AGR" -> Nat. Gas AGR | F13: PJ | L13: INDNGA | M13: Nat. Gas IND
D14: ="AGR"&RIGHT(L14,LEN(L14)-3) -> AGRCOA | E14: =LEFT(M14,LEN(M14)-3)&" AGR" -> Coal AGR | F14: PJ | L14: INDCOA | M14: Coal IND
D15: ="AGR"&RIGHT(L15,LEN(L15)-3) -> AGRDSL | E15: =LEFT(M15,LEN(M15)-3)&" AGR" -> Diesel AGR | F15: PJ | L15: INDDSL | M15: Diesel IND
D16: ="AGR"&RIGHT(L16,LEN(L16)-3) -> AGRWPE | E16: =LEFT(M16,LEN(M16)-3)&" AGR" -> Wood Pellets AGR | F16: PJ | L16: INDWPE | M16: Wood Pellets IND
D17: ="AGR"&RIGHT(L17,LEN(L17)-3) -> AGRWCH | E17: =LEFT(M17,LEN(M17)-3)&" AGR" -> Wood chips and wood waste AGR | F17: PJ | L17: INDWCH | M17: Wood chips and wood waste IND
D18: ="AGR"&RIGHT(L18,LEN(L18)-3) -> AGRBGA | E18: =LEFT(M18,LEN(M18)-3)&" AGR" -> Biogas AGR | F18: PJ | L18: INDBGA | M18: Biogas IND
D19: ="AGR"&RIGHT(L19,LEN(L19)-3) -> AGRHFO | E19: =LEFT(M19,LEN(M19)-3)&" AGR" -> Heavy Fuel Oil AGR | F19: PJ | L19: INDHFO | M19: Heavy Fuel Oil IND
D20: ="AGR"&RIGHT(L20,LEN(L20)-3) -> AGRLPG | E20: =LEFT(M20,LEN(M20)-3)&" AGR" -> Liquid petrol gas AGR | F20: PJ | L20: INDLPG | M20: Liquid petrol gas IND
D21: ="AGR"&RIGHT(L21,LEN(L21)-3) -> AGRWST | E21: =LEFT(M21,LEN(M21)-3)&" AGR" -> Waste AGR | F21: PJ | L21: INDWST | M21: Waste IND
D22: ="AGR"&RIGHT(L22,LEN(L22)-3) -> AGRHCE | E22: =LEFT(M22,LEN(M22)-3)&" AGR" -> Centralised District Heat AGR | F22: PJ | H22: DAYNITE | L22: INDHCE | M22: Centralised District Heat IND
D23: ="AGR"&RIGHT(L23,LEN(L23)-3) -> AGRHSE | E23: =LEFT(M23,LEN(M23)-3)&" AGR" -> SubUrban District Heat AGR | F23: PJ | H23: DAYNITE | L23: INDHSE | M23: SubUrban District Heat IND
D24: ="AGR"&RIGHT(L24,LEN(L24)-3) -> AGRHDE | E24: =LEFT(M24,LEN(M24)-3)&" AGR" -> Decentralised District Heat AGR | F24: PJ | H24: DAYNITE | L24: INDHDE | M24: Decentralised District Heat IND
D25: ="AGR"&RIGHT(L25,LEN(L25)-3) -> AGRELC | E25: =LEFT(M25,LEN(M25)-3)&" AGR" -> Electricity AGR | F25: PJ | H25: DAYNITE | J25: ELC | L25: INDELC | M25: Electricity IND
D26: ="AGR"&RIGHT(L26,LEN(L26)-3) -> AGRSOL | E26: =LEFT(M26,LEN(M26)-3)&" AGR" -> Solar AGR | F26: PJ | L26: INDSOL | M26: Solar IND
D27: ="AGR"&RIGHT(L27,LEN(L27)-3) -> AGRDSB1 | E27: =LEFT(M27,LEN(M27)-3)&" AGR" -> Biodiesel 1. generation AGR | F27: PJ | L27: INDDSB1 | M27: Biodiesel 1. generation IND
D28: ="AGR"&RIGHT(L28,LEN(L28)-3) -> AGRDSB2 | E28: =LEFT(M28,LEN(M28)-3)&" AGR" -> Biodiesel 2. generation AGR | F28: PJ | L28: INDDSB2 | M28: Biodiesel 2. generation IND
D29: ="AGR"&RIGHT(L29,LEN(L29)-3) -> AGRSNG1 | E29: =LEFT(M29,LEN(M29)-3)&" AGR" -> Bio Synt. Nat. Gas 1. generation AGR | F29: PJ | L29: INDSNG1 | M29: Bio Synt. Nat. Gas 1. generation IND
D30: ="AGR"&RIGHT(L30,LEN(L30)-3) -> AGRSNG2 | E30: =LEFT(M30,LEN(M30)-3)&" AGR" -> Bio Synt. Nat. Gas 2. generation AGR | F30: PJ | L30: INDSNG2 | M30: Bio Synt. Nat. Gas 2. generation IND
D31: ="AGR"&RIGHT(L31,LEN(L31)-3) -> AGRGSL | E31: =LEFT(M31,LEN(M31)-3)&" AGR" -> Gasoline AGR | F31: PJ | L31: INDGSL | M31: Gasoline IND
D32: ="AGR"&RIGHT(L32,LEN(L32)-3) -> AGRGSB1 | E32: =LEFT(M32,LEN(M32)-3)&" AGR" -> Bioethanol 1. generation AGR | F32: PJ | L32: INDGSB1 | M32: Bioethanol 1. generation IND
D33: ="AGR"&RIGHT(L33,LEN(L33)-3) -> AGRGSB2 | E33: =LEFT(M33,LEN(M33)-3)&" AGR" -> Bioethanol 2. generation AGR | F33: PJ | L33: INDGSB2 | M33: Bioethanol 2. generation IND
D34: ="AGR"&RIGHT(L34,LEN(L34)-3) -> AGRH2 | E34: =LEFT(M34,LEN(M34)-3)&" AGR" -> Hydrogen AGR | F34: PJ | L34: INDH2 | M34: Hydrogen IND
D35: ="AGR"&RIGHT(L35,LEN(L35)-3) -> AGRBLQ | E35: =LEFT(M35,LEN(M35)-3)&" AGR" -> Black liquor AGR | F35: PJ | L35: INDBLQ | M35: Black liquor IND
B36: ENV | D36: AGRCO2 | E36: CO2 Agriculture | F36: kt

Sheet Demand
B2: =Agriculture!V76 -> 2010 | C2: Demand | I2: Information for function INDIRECT():
B3: DEMAND | D3: Block size: | E3: 7
I4: This colour: Input
B5: ~FI_T
B6: CommName | C6: *Description | D6: *Unit | E6: DEMAND~DE1 | F6: DEMAND~DE2 | G6: DEMAND~DE3 | I6: Sheet | J6: DE1 Col | K6: DE2 Col | L6: DE3 Col | M6: Row 1 | N6: Row 2 | P6: Check
B7: =+Commodities!D6 -> AGDPH | C7: =+Commodities!E6 -> Agriculture Demand Process heat | D7: =+Commodities!F6 -> PJ | E7: =+SUM(INDIRECT("'" & $I7 & "'!" & J7 & $M7 & IF(ISBLANK($N7),"",":" & J7 & $N7))) -> 30.21547 | F7: =+SUM(INDIRECT("'" & $I7 & "'!" & K7 & $M7 & IF(ISBLANK($N7),"",":" & K7 & $N7))) -> 0 | G7: =+SUM(INDIRECT("'" & $I7 & "'!" & L7 & $M7 & IF(ISBLANK($N7),"",":" & L7 & $N7))) -> 0 | I7: =Commodities!AE6 -> Agriculture | J7: =SUBSTITUTE(ADDRESS(1,COLUMN(Agriculture!AQ1),4),"1","") -> AQ | K7: =SUBSTITUTE(ADDRESS(1,COLUMN(Agriculture!AR1),4),"1","") -> AR | L7: =SUBSTITUTE(ADDRESS(1,COLUMN(Agriculture!AS1),4),"1","") -> AS | M7: 26 | N7: 37 | P7: =+SUM(INDIRECT("'" & I7 & "'!" & "AQ26:AR62")) - SUM(E7:F13) -> 0
B8: =+Commodities!D7 -> AGDCO | C8: =+Commodities!E7 -> Agriculture Demand Cooling | D8: =+Commodities!F7 -> PJ | E8: =+SUM(INDIRECT("'" & $I8 & "'!" & J8 & $M8 & IF(ISBLANK($N8),"",":" & J8 & $N8))) -> 1.9300122 | F8: =+SUM(INDIRECT("'" & $I8 & "'!" & K8 & $M8 & IF(ISBLANK($N8),"",":" & K8 & $N8))) -> 0 | G8: =+SUM(INDIRECT("'" & $I8 & "'!" & L8 & $M8 & IF(ISBLANK($N8),"",":" & L8 & $N8))) -> 0 | I8: =+I7 -> Agriculture | J8: =+J7 -> AQ | K8: =+K7 -> AR | L8: =+L7 -> AS | M8: 38 | N8: 46
B9: =+Commodities!D8 -> AGDSH | C9: =+Commodities!E8 -> Agriculture Demand Spatial Heat | D9: =+Commodities!F8 -> PJ | E9: =+SUM(INDIRECT("'" & $I9 & "'!" & J9 & $M9 & IF(ISBLANK($N9),"",":" & J9 & $N9))) -> 0.62730814 | F9: =+SUM(INDIRECT("'" & $I9 & "'!" & K9 & $M9 & IF(ISBLANK($N9),"",":" & K9 & $N9))) -> 0 | G9: =+SUM(INDIRECT("'" & $I9 & "'!" & L9 & $M9 & IF(ISBLANK($N9),"",":" & L9 & $N9))) -> 0 | I9: =+I8 -> Agriculture | J9: =+J8 -> AQ | K9: =+K8 -> AR | L9: =+L8 -> AS | M9: 47 | N9: 58
B10: =+Commodities!D9 -> AGDLA | C10: =+Commodities!E9 -> Agriculture Demand Light | D10: =+Commodities!F9 -> PJ | E10: =+SUM(INDIRECT("'" & $I10 & "'!" & J10 & $M10 & IF(ISBLANK($N10),"",":" & J10 & $N10))) -> 4.6211625 | F10: =+SUM(INDIRECT("'" & $I10 & "'!" & K10 & $M10 & IF(ISBLANK($N10),"",":" & K10 & $N10))) -> 0 | G10: =+SUM(INDIRECT("'" & $I10 & "'!" & L10 & $M10 & IF(ISBLANK($N10),"",":" & L10 & $N10))) -> 0 | I10: =+I9 -> Agriculture | J10: =+J9 -> AQ | K10: =+K9 -> AR | L10: =+L9 -> AS | M10: 59
B11: =+Commodities!D10 -> AGDEM | C11: =+Commodities!E10 -> Agriculture Demand Electric Motors | D11: =+Commodities!F10 -> PJ | E11: =+SUM(INDIRECT("'" & $I11 & "'!" & J11 & $M11 & IF(ISBLANK($N11),"",":" & J11 & $N11))) -> 13.831969 | F11: =+SUM(INDIRECT("'" & $I11 & "'!" & K11 & $M11 & IF(ISBLANK($N11),"",":" & K11 & $N11))) -> 0 | G11: =+SUM(INDIRECT("'" & $I11 & "'!" & L11 & $M11 & IF(ISBLANK($N11),"",":" & L11 & $N11))) -> 0 | I11: =+I10 -> Agriculture | J11: =+J10 -> AQ | K11: =+K10 -> AR | L11: =+L10 -> AS | M11: 60
B12: =+Commodities!D11 -> AGDTF | C12: =+Commodities!E11 -> Agriculture Demand Haulage Tractors, Trucks, Fishing boats, Forest machines | D12: =+Commodities!F11 -> PJ | E12: =+SUM(INDIRECT("'" & $I12 & "'!" & J12 & $M12 & IF(ISBLANK($N12),"",":" & J12 & $N12))) -> 1.571372 | F12: =+SUM(INDIRECT("'" & $I12 & "'!" & K12 & $M12 & IF(ISBLANK($N12),"",":" & K12 & $N12))) -> 0 | G12: =+SUM(INDIRECT("'" & $I12 & "'!" & L12 & $M12 & IF(ISBLANK($N12),"",":" & L12 & $N12))) -> 0 | I12: =+I11 -> Agriculture | J12: =+J11 -> AQ | K12: =+K11 -> AR | L12: =+L11 -> AS | M12: 61
B13: =+Commodities!D12 -> AGDFL | C13: =+Commodities!E12 -> Agriculture Demand Haulage Forklifts | D13: =+Commodities!F12 -> PJ | E13: =+SUM(INDIRECT("'" & $I13 & "'!" & J13 & $M13 & IF(ISBLANK($N13),"",":" & J13 & $N13))) -> 0 | F13: =+SUM(INDIRECT("'" & $I13 & "'!" & K13 & $M13 & IF(ISBLANK($N13),"",":" & K13 & $N13))) -> 0 | G13: =+SUM(INDIRECT("'" & $I13 & "'!" & L13 & $M13 & IF(ISBLANK($N13),"",":" & L13 & $N13))) -> 0 | I13: =+I12 -> Agriculture | J13: =+J12 -> AQ | K13: =+K12 -> AR | L13: =+L12 -> AS | M13: 62
B18: 2015 | C18: Demand
I19: Information for function INDIRECT():
B20: DEMAND | D20: Block size: | E20: 7
I21: This colour: Input
B22: ~FI_T
B23: CommName | C23: *Description | D23: *Unit | E23: DEMAND~DE1~2015 | F23: DEMAND~DE2~2015 | G23: DEMAND~DE3~2015 | I23: Sheet | J23: DE1 Col | K23: DE2 Col | L23: DE2 Col | M23: Row 1 | N23: Row 2 | P23: Check
B24: =B7 -> AGDPH | C24: =C7 -> Agriculture Demand Process heat | D24: =D7 -> PJ | E24: =+SUM(INDIRECT("'" & $I24 & "'!" & J24 & $M24 & IF(ISBLANK($N24),"",":" & J24 & $N24))) -> 0 | F24: =+SUM(INDIRECT("'" & $I24 & "'!" & K24 & $M24 & IF(ISBLANK($N24),"",":" & K24 & $N24))) -> 0 | G24: =+SUM(INDIRECT("'" & $I24 & "'!" & L24 & $M24 & IF(ISBLANK($N24),"",":" & L24 & $N24))) -> 0 | I24: =I7 -> Agriculture | J24: =SUBSTITUTE(ADDRESS(1,COLUMN(Agriculture!BD1),4),"1","") -> BD | K24: =SUBSTITUTE(ADDRESS(1,COLUMN(Agriculture!BE1),4),"1","") -> BE | L24: =SUBSTITUTE(ADDRESS(1,COLUMN(Agriculture!BF1),4),"1","") -> BF | M24: =M7 -> 26 | N24: =N7 -> 37 | P24: =+SUM(INDIRECT("'" & I24 & "'!" & "BD26:BE62")) - SUM(E24:F30) -> 0
B25: =B8 -> AGDCO | C25: =C8 -> Agriculture Demand Cooling | D25: =D8 -> PJ | E25: =+SUM(INDIRECT("'" & $I25 & "'!" & J25 & $M25 & IF(ISBLANK($N25),"",":" & J25 & $N25))) -> 1.8193222 | F25: =+SUM(INDIRECT("'" & $I25 & "'!" & K25 & $M25 & IF(ISBLANK($N25),"",":" & K25 & $N25))) -> 0 | G25: =+SUM(INDIRECT("'" & $I25 & "'!" & L25 & $M25 & IF(ISBLANK($N25),"",":" & L25 & $N25))) -> 0 | I25: =I8 -> Agriculture | J25: =+J24 -> BD | K25: =+K24 -> BE | L25: =+L24 -> BF | M25: =M8 -> 38 | N25: =N8 -> 46
B26: =B9 -> AGDSH | C26: =C9 -> Agriculture Demand Spatial Heat | D26: =D9 -> PJ | E26: =+SUM(INDIRECT("'" & $I26 & "'!" & J26 & $M26 & IF(ISBLANK($N26),"",":" & J26 & $N26))) -> 0.5913308 | F26: =+SUM(INDIRECT("'" & $I26 & "'!" & K26 & $M26 & IF(ISBLANK($N26),"",":" & K26 & $N26))) -> 0 | G26: =+SUM(INDIRECT("'" & $I26 & "'!" & L26 & $M26 & IF(ISBLANK($N26),"",":" & L26 & $N26))) -> 0 | I26: =I9 -> Agriculture | J26: =+J25 -> BD | K26: =+K25 -> BE | L26: =+L25 -> BF | M26: =M9 -> 47 | N26: =N9 -> 58
B27: =B10 -> AGDLA | C27: =C10 -> Agriculture Demand Light | D27: =D10 -> PJ | E27: =+SUM(INDIRECT("'" & $I27 & "'!" & J27 & $M27 & IF(ISBLANK($N27),"",":" & J27 & $N27))) -> 4.3561298 | F27: =+SUM(INDIRECT("'" & $I27 & "'!" & K27 & $M27 & IF(ISBLANK($N27),"",":" & K27 & $N27))) -> 0 | G27: =+SUM(INDIRECT("'" & $I27 & "'!" & L27 & $M27 & IF(ISBLANK($N27),"",":" & L27 & $N27))) -> 0 | I27: =I10 -> Agriculture | J27: =+J26 -> BD | K27: =+K26 -> BE | L27: =+L26 -> BF | M27: =M10 -> 59
B28: =B11 -> AGDEM | C28: =C11 -> Agriculture Demand Electric Motors | D28: =D11 -> PJ | E28: =+SUM(INDIRECT("'" & $I28 & "'!" & J28 & $M28 & IF(ISBLANK($N28),"",":" & J28 & $N28))) -> 13.038679 | F28: =+SUM(INDIRECT("'" & $I28 & "'!" & K28 & $M28 & IF(ISBLANK($N28),"",":" & K28 & $N28))) -> 0 | G28: =+SUM(INDIRECT("'" & $I28 & "'!" & L28 & $M28 & IF(ISBLANK($N28),"",":" & L28 & $N28))) -> 0 | I28: =I11 -> Agriculture | J28: =+J27 -> BD | K28: =+K27 -> BE | L28: =+L27 -> BF | M28: =M11 -> 60
B29: =B12 -> AGDTF | C29: =C12 -> Agriculture Demand Haulage Tractors, Trucks, Fishing boats, Forest machines | D29: =D12 -> PJ | E29: =+SUM(INDIRECT("'" & $I29 & "'!" & J29 & $M29 & IF(ISBLANK($N29),"",":" & J29 & $N29))) -> 0.354801 | F29: =+SUM(INDIRECT("'" & $I29 & "'!" & K29 & $M29 & IF(ISBLANK($N29),"",":" & K29 & $N29))) -> 0 | G29: =+SUM(INDIRECT("'" & $I29 & "'!" & L29 & $M29 & IF(ISBLANK($N29),"",":" & L29 & $N29))) -> 0 | I29: =I12 -> Agriculture | J29: =+J28 -> BD | K29: =+K28 -> BE | L29: =+L28 -> BF | M29: =M12 -> 61
B30: =B13 -> AGDFL | C30: =C13 -> Agriculture Demand Haulage Forklifts | D30: =D13 -> PJ | E30: =+SUM(INDIRECT("'" & $I30 & "'!" & J30 & $M30 & IF(ISBLANK($N30),"",":" & J30 & $N30))) -> 0 | F30: =+SUM(INDIRECT("'" & $I30 & "'!" & K30 & $M30 & IF(ISBLANK($N30),"",":" & K30 & $N30))) -> 0 | G30: =+SUM(INDIRECT("'" & $I30 & "'!" & L30 & $M30 & IF(ISBLANK($N30),"",":" & L30 & $N30))) -> 0 | I30: =I13 -> Agriculture | J30: =+J29 -> BD | K30: =+K29 -> BE | L30: =+L29 -> BF | M30: =M13 -> 62
B35: =Agriculture!V126 -> 2019 | C35: Demand
I36: Information for function INDIRECT():
B37: DEMAND | D37: Block size: | E37: 7
I38: This colour: Input
B39: ~FI_T
B40: CommName | C40: *Description | D40: *Unit | E40: DEMAND~DE1~2019 | F40: DEMAND~DE2~2019 | G40: DEMAND~DE3~2019 | I40: Sheet | J40: DE1 Col | K40: DE2 Col | L40: DE2 Col | M40: Row 1 | N40: Row 2 | P40: Check
B41: =B7 -> AGDPH | C41: =C7 -> Agriculture Demand Process heat | D41: =D7 -> PJ | E41: =+SUM(INDIRECT("'" & $I41 & "'!" & J41 & $M41 & IF(ISBLANK($N41),"",":" & J41 & $N41))) -> 39.988841 | F41: =+SUM(INDIRECT("'" & $I41 & "'!" & K41 & $M41 & IF(ISBLANK($N41),"",":" & K41 & $N41))) -> 0 | G41: =+SUM(INDIRECT("'" & $I41 & "'!" & L41 & $M41 & IF(ISBLANK($N41),"",":" & L41 & $N41))) -> 0 | I41: =I24 -> Agriculture | J41: =SUBSTITUTE(ADDRESS(1,COLUMN(Agriculture!BQ1),4),"1","") -> BQ | K41: =SUBSTITUTE(ADDRESS(1,COLUMN(Agriculture!BR1),4),"1","") -> BR | L41: =SUBSTITUTE(ADDRESS(1,COLUMN(Agriculture!BS1),4),"1","") -> BS | M41: =M24 -> 26 | N41: =N24 -> 37 | P41: =+SUM(INDIRECT("'" & I41 & "'!" & "BQ26:BR62")) - SUM(E41:F47) -> 0
B42: =B8 -> AGDCO | C42: =C8 -> Agriculture Demand Cooling | D42: =D8 -> PJ | E42: =+SUM(INDIRECT("'" & $I42 & "'!" & J42 & $M42 & IF(ISBLANK($N42),"",":" & J42 & $N42))) -> 1.661663 | F42: =+SUM(INDIRECT("'" & $I42 & "'!" & K42 & $M42 & IF(ISBLANK($N42),"",":" & K42 & $N42))) -> 0 | G42: =+SUM(INDIRECT("'" & $I42 & "'!" & L42 & $M42 & IF(ISBLANK($N42),"",":" & L42 & $N42))) -> 0 | I42: =I25 -> Agriculture | J42: =+J41 -> BQ | K42: =+K41 -> BR | L42: =+L41 -> BS | M42: =M25 -> 38 | N42: =N25 -> 46
B43: =B9 -> AGDSH | C43: =C9 -> Agriculture Demand Spatial Heat | D43: =D9 -> PJ | E43: =+SUM(INDIRECT("'" & $I43 & "'!" & J43 & $M43 & IF(ISBLANK($N43),"",":" & J43 & $N43))) -> 0.54008712 | F43: =+SUM(INDIRECT("'" & $I43 & "'!" & K43 & $M43 & IF(ISBLANK($N43),"",":" & K43 & $N43))) -> 0 | G43: =+SUM(INDIRECT("'" & $I43 & "'!" & L43 & $M43 & IF(ISBLANK($N43),"",":" & L43 & $N43))) -> 0 | I43: =I26 -> Agriculture | J43: =+J42 -> BQ | K43: =+K42 -> BR | L43: =+L42 -> BS | M43: =M26 -> 47 | N43: =N26 -> 58
B44: =B10 -> AGDLA | C44: =C10 -> Agriculture Demand Light | D44: =D10 -> PJ | E44: =+SUM(INDIRECT("'" & $I44 & "'!" & J44 & $M44 & IF(ISBLANK($N44),"",":" & J44 & $N44))) -> 3.9786353 | F44: =+SUM(INDIRECT("'" & $I44 & "'!" & K44 & $M44 & IF(ISBLANK($N44),"",":" & K44 & $N44))) -> 0 | G44: =+SUM(INDIRECT("'" & $I44 & "'!" & L44 & $M44 & IF(ISBLANK($N44),"",":" & L44 & $N44))) -> 0 | I44: =I27 -> Agriculture | J44: =+J43 -> BQ | K44: =+K43 -> BR | L44: =+L43 -> BS | M44: =M27 -> 59
B45: =B11 -> AGDEM | C45: =C11 -> Agriculture Demand Electric Motors | D45: =D11 -> PJ | E45: =+SUM(INDIRECT("'" & $I45 & "'!" & J45 & $M45 & IF(ISBLANK($N45),"",":" & J45 & $N45))) -> 11.90877 | F45: =+SUM(INDIRECT("'" & $I45 & "'!" & K45 & $M45 & IF(ISBLANK($N45),"",":" & K45 & $N45))) -> 0 | G45: =+SUM(INDIRECT("'" & $I45 & "'!" & L45 & $M45 & IF(ISBLANK($N45),"",":" & L45 & $N45))) -> 0 | I45: =I28 -> Agriculture | J45: =+J44 -> BQ | K45: =+K44 -> BR | L45: =+L44 -> BS | M45: =M28 -> 60
B46: =B12 -> AGDTF | C46: =C12 -> Agriculture Demand Haulage Tractors, Trucks, Fishing boats, Forest machines | D46: =D12 -> PJ | E46: =+SUM(INDIRECT("'" & $I46 & "'!" & J46 & $M46 & IF(ISBLANK($N46),"",":" & J46 & $N46))) -> 84.016547 | F46: =+SUM(INDIRECT("'" & $I46 & "'!" & K46 & $M46 & IF(ISBLANK($N46),"",":" & K46 & $N46))) -> 0 | G46: =+SUM(INDIRECT("'" & $I46 & "'!" & L46 & $M46 & IF(ISBLANK($N46),"",":" & L46 & $N46))) -> 0 | I46: =I29 -> Agriculture | J46: =+J45 -> BQ | K46: =+K45 -> BR | L46: =+L45 -> BS | M46: =M29 -> 61
B47: =B13 -> AGDFL | C47: =C13 -> Agriculture Demand Haulage Forklifts | D47: =D13 -> PJ | E47: =+SUM(INDIRECT("'" & $I47 & "'!" & J47 & $M47 & IF(ISBLANK($N47),"",":" & J47 & $N47))) -> 6.6226275 | F47: =+SUM(INDIRECT("'" & $I47 & "'!" & K47 & $M47 & IF(ISBLANK($N47),"",":" & K47 & $N47))) -> 0 | G47: =+SUM(INDIRECT("'" & $I47 & "'!" & L47 & $M47 & IF(ISBLANK($N47),"",":" & L47 & $N47))) -> 0 | I47: =I30 -> Agriculture | J47: =+J46 -> BQ | K47: =+K46 -> BR | L47: =+L46 -> BS | M47: =M30 -> 62

Sheet Agriculture
C2: Index: 1 - 9 | D2: 1 | E2: In sheets 'Commodities', 'Processes', 'Pivot Agg 1' and 'Energy matrix'
C4: Sheet: | D4: Commodities
C5: Sector: | D5: =+INDEX(Commodities!$X$6:$X$6,D2) -> Agriculture
D6: =+INDEX(Commodities!$Y$6:$Y$6,D2) -> Agriculture, forestry and fishing | F6: =+"Give 'Index' in cell " & SUBSTITUTE(CELL("address",D2),"$","") & "." -> Give 'Index' in cell D2.
F7: Values: 1 to 10.
C8: Sheet: | D8: Processes
C9: Sector: | D9: =+OFFSET(Processes!$M$11,D11,0) -> Agriculture, forestry and fishing
C10: Block size: | D10: =+ROW(Processes!$M$44) - ROW(Processes!$M$7) -> 37
C11: Block offset: | D11: =+$D$10*$D$2-$D$10 -> 0
C13: Sheet: | D13: Energy matrix
C14: Sector: | D14: =+INDEX('Energy matrix'!$C$4:$N$4,1,D2) -> Agriculture, forestry and fishing
G19: Relaxation factor for calibration | AK19: 2010 | AX19: 2015 | BK19: 2019
G20: 2010 | J20: 2015 | M20: 2019
G21: 1.001 | H21: 1.001 | I21: 1.001 | J21: 1.01 | K21: 1.01 | L21: 1.01 | M21: 1.01 | N21: 1.01 | O21: 1.01 | AN21: Energy service demand | BA21: Energy service demand | BN21: Energy service demand
AN22: DE1 | AO22: DE2 | AP22: DE3 | BA22: DE1 | BB22: DE2 | BC22: DE3 | BN22: DE1 | BO22: DE2 | BP22: DE3
F23: ~FI_T | AN23: {=INDEX(RegSplit!$B$4:$AN$6,MATCH(AN22,RegSplit!$A$4:$A$6,0),MATCH($D$6&AK19,RegSplit!$B$2:$AN$2&RegSplit!$B$3:$AN$3,0))} -> 1 | AO23: {=INDEX(RegSplit!$B$4:$AN$6,MATCH(AO22,RegSplit!$A$4:$A$6,0),MATCH($D$6&AK19,RegSplit!$B$2:$AN$2&RegSplit!$B$3:$AN$3,0))} -> 0 | AP23: {=INDEX(RegSplit!$B$4:$AN$6,MATCH(AP22,RegSplit!$A$4:$A$6,0),MATCH($D$6&AK19,RegSplit!$B$2:$AN$2&RegSplit!$B$3:$AN$3,0))} -> 0 | BA23: {=INDEX(RegSplit!$B$4:$AN$6,MATCH(BA22,RegSplit!$A$4:$A$6,0),MATCH($D$6&AX19,RegSplit!$B$2:$AN$2&RegSplit!$B$3:$AN$3,0))} -> 1 | BB23: {=INDEX(RegSplit!$B$4:$AN$6,MATCH(BB22,RegSplit!$A$4:$A$6,0),MATCH($D$6&AX19,RegSplit!$B$2:$AN$2&RegSplit!$B$3:$AN$3,0))} -> 0 | BC23: {=INDEX(RegSplit!$B$4:$AN$6,MATCH(BC22,RegSplit!$A$4:$A$6,0),MATCH($D$6&AX19,RegSplit!$B$2:$AN$2&RegSplit!$B$3:$AN$3,0))} -> 0 | BN23: {=INDEX(RegSplit!$B$4:$AN$6,MATCH(BN22,RegSplit!$A$4:$A$6,0),MATCH($D$6&BK19,RegSplit!$B$2:$AN$2&RegSplit!$B$3:$AN$3,0))} -> 1 | BO23: {=INDEX(RegSplit!$B$4:$AN$6,MATCH(BO22,RegSplit!$A$4:$A$6,0),MATCH($D$6&BK19,RegSplit!$B$2:$AN$2&RegSplit!$B$3:$AN$3,0))} -> 0 | BP23: {=INDEX(RegSplit!$B$4:$AN$6,MATCH(BP22,RegSplit!$A$4:$A$6,0),MATCH($D$6&BK19,RegSplit!$B$2:$AN$2&RegSplit!$B$3:$AN$3,0))} -> 0
C24: TechName | D24: *TechDesc | E24: Comm-IN | F24: Comm-OUT | G24: STOCK~DE1 | H24: STOCK~DE2 | I24: STOCK~DE3 | J24: STOCK~DE1~2015 | K24: STOCK~DE2~2015 | L24: STOCK~DE3~2015 | M24: STOCK~DE1~2019 | N24: STOCK~DE2~2019 | O24: STOCK~DE3~2019 | P24: STOCK~DE1~2020 | Q24: STOCK~DE2~2020 | R24: STOCK~DE3~2020 | S24: STOCK~DE1~2034 | T24: STOCK~DE2~2034 | U24: STOCK~DE3~2034 | V24: STOCK~0 | W24: EFF~DE1 | X24: EFF~DE2 | Y24: EFF~DE3 | Z24: CAPUNIT | AA24: AFA | AB24: LIFE | AC24: Share-I~UP | AD24: Share-I~UP~2014 | AE24: Share-I~UP~0 | AM24: Fuel demand by energy service | AQ24: Energy service demand | AT24: Fuel demand (calculated) | AZ24: Fuel demand by energy service | BD24: Energy service demand | BG24: Fuel demand (calculated) | BM24: Fuel demand by energy service | BQ24: Energy service demand | BT24: Fuel demand (calculated)
C25: *Unit | G25: MW | H25: MW | J25: MW | K25: MW | M25: MW | N25: MW | P25: MW | Q25: MW | S25: MW | T25: MW | V25: Interpolation | W25: PJ/PJ | X25: PJ/PJ | Z25: KW/PJ | AB25: Year | AE25: Interpolation | AG25: 2010 | AH25: 2015 | AI25: 2019 | AL25: PJ | AM25: Demand base year | AN25: DE1 | AO25: DE2 | AP25: DE3 | AQ25: DE1 | AR25: DE2 | AS25: DE3 | AT25: DE1 | AU25: DE2 | AV25: DE3 | AY25: PJ | AZ25: Demand base year | BA25: DE1 | BB25: DE2 | BC25: DE3 | BD25: DE1 | BE25: DE2 | BF25: DE3 | BG25: DE1 | BH25: DE2 | BI25: DE3 | BL25: PJ | BM25: Demand base year | BN25: DE1 | BO25: DE2 | BP25: DE3 | BQ25: DE1 | BR25: DE2 | BS25: DE3 | BT25: DE1 | BU25: DE2 | BV25: DE3
C26: =+IF(OFFSET(Processes!B7,$D$11,0)="*","*",OFFSET(Processes!D7,$D$11,0)) -> AGRPHBNGAE1 | D26: =+OFFSET(Processes!E7,$D$11,0) -> Agriculture Heat Medium Temp. Boiler - Nat. Gas Existing 1 | E26: =+Processes!O7 -> AGRSNG1,AGRSNG2,AGRNGA | F26: =Commodities!$D$6 -> AGDPH | G26: =AN26/($Z26*$AA26)*G$21*W26 -> 876.73422 | H26: =AO26/($Z26*$AA26)*H$21*X26 -> 0 | I26: =AP26/($Z26*$AA26)*I$21*Y26 -> 0 | J26: =BA26/($Z26*$AA26)*J$21*W26 -> 0 | K26: =BB26/($Z26*$AA26)*K$21*X26 -> 0 | L26: =BC26/($Z26*$AA26)*L$21*Y26 -> 0 | M26: =BN26/($Z26*$AA26)*M$21*W26 -> 690.75498 | N26: =BO26/($Z26*$AA26)*N$21*X26 -> 0 | O26: =BP26/($Z26*$AA26)*O$21*Y26 -> 0 | P26: =M26 -> 690.75498 | Q26: =N26 -> 0 | R26: =O26 -> 0 | S26: =IF($AB26=20,0,M26/5)*IF(M26=0,0,1) -> 0 | T26: =IF($AB26=20,0,N26/5)*IF(N26=0,0,1) -> 0 | U26: =IF($AB26=20,0,O26/5)*IF(O26=0,0,1) -> 0 | V26: 5 | W26: =I146 -> 0.9996 | X26: =W26 -> 0.9996 | Y26: =X26 -> 0.9996 | Z26: =3.6*8760/1000000 -> 0.031536 | AA26: 0.5 | AB26: 20 | AG26: =((G26*Z26*AA26/W26)+(H26*Z26*AA26/X26))/$G$21 -> 13.816061 | AH26: =((J26*Z26*AA26/W26)+(K26*Z26*AA26/X26))/$J$21 -> 0 | AI26: =((M26*AA26*Z26/W26)+(N26*Z26*AA26/X26))/$M$21 -> 10.7883 | AJ26: Coal | AK26: =F26 -> AGDPH | AL26: NGA | AM26: =(I77+J77)/1000 -> 13.816061 | AN26: =AM26*$AN$23 -> 13.816061 | AO26: =AM26*$AO$23 -> 0 | AP26: =AM26*$AP$23 -> 0 | AQ26: =IFERROR(G26*$Z26*$AA26/G$21,0) -> 13.810535 | AR26: =IFERROR(H26*$Z26*$AA26/H$21,0) -> 0 | AS26: =IFERROR(I26*$Z26*$AA26/I$21,0) -> 0 | AT26: =IFERROR(AQ26/W26,0) -> 13.816061 | AU26: =IFERROR(AR26/X26,0) -> 0 | AV26: =IFERROR(AS26/Y26,0) -> 0 | AX26: =AK26 -> AGDPH | AY26: NGA | AZ26: =(J102+I102)/1000 -> 13.2966 | BA26: =DE26*$AN$23 -> 0 | BB26: =DE26*$BB$23 -> 0 | BC26: =DE26*$BC$23 -> 0 | BD26: =IFERROR(J26*$Z26*AA26/J$21,0) -> 0 | BE26: =IFERROR(K26*$Z26*AA26/K$21,0) -> 0 | BF26: =IFERROR(L26*$Z26*AA26/L$21,0) -> 0 | BG26: =IFERROR(BD26/W26,0) -> 0 | BH26: =IFERROR(BE26/X26,0) -> 0 | BI26: =IFERROR(BF26/Y26,0) -> 0 | BK26: =AK26 -> AGDPH | BL26: NGA | BM26: =(J127+I127)/1000 -> 10.7883 | BN26: =BM26*$AN$23 -> 10.7883 | BO26: =BM26*$BB$23 -> 0 | BP26: =BM26*$BC$23 -> 0 | BQ26: =IFERROR(M26*$Z26*$AA26/M$21,0) -> 10.783985 | BR26: =IFERROR(N26*$Z26*$AA26/N$21,0) -> 0 | BS26: =IFERROR(O26*$Z26*$AA26/O$21,0) -> 0 | BT26: =IFERROR(BQ26/W26,0) -> 10.7883 | BU26: =IFERROR(BR26/X26,0) -> 0 | BV26: =IFERROR(BS26/Y26,0) -> 0
C27: =+IF(OFFSET(Processes!B8,$D$11,0)="*","*",OFFSET(Processes!D8,$D$11,0)) -> AGRPHBCOAE1 | D27: =+OFFSET(Processes!E8,$D$11,0) -> Agriculture Heat Medium Temp. Boiler - Coal Existing 1 | E27: =+Processes!O8 -> AGRCOA | F27: =Commodities!$D$6 -> AGDPH | G27: =AN27/($Z27*$AA27)*G$21*W27 -> 0 | H27: =AO27/($Z27*$AA27)*H$21*X27 -> 0 | I27: =AP27/($Z27*$AA27)*I$21*Y27 -> 0 | J27: =BA27/($Z27*$AA27)*J$21*W27 -> 0 | K27: =BB27/($Z27*$AA27)*K$21*X27 -> 0 | L27: =BC27/($Z27*$AA27)*L$21*Y27 -> 0 | M27: =BN27/($Z27*$AA27)*M$21*W27 -> 0 | N27: =BO27/($Z27*$AA27)*N$21*X27 -> 0 | O27: =BP27/($Z27*$AA27)*O$21*Y27 -> 0 | P27: =M27 -> 0 | Q27: =N27 -> 0 | R27: =O27 -> 0 | S27: =IF($AB27=20,0,M27/5)*IF(M27=0,0,1) -> 0 | T27: =IF($AB27=20,0,N27/5)*IF(N27=0,0,1) -> 0 | U27: =IF($AB27=20,0,O27/5)*IF(O27=0,0,1) -> 0 | V27: 5 | W27: =D146 -> 0.931 | X27: =W27 -> 0.931 | Y27: =X27 -> 0.931 | Z27: =3.6*8760/1000000 -> 0.031536 | AA27: =$AA$26 -> 0.5 | AB27: 20 | AG27: =((G27*Z27*AA27/W27)+(H27*Z27*AA27/X27))/$G$21 -> 0 | AH27: =((J27*Z27*AA27/W27)+(K27*Z27*AA27/X27))/$J$21 -> 0 | AI27: =((M27*AA27*Z27/W27)+(N27*Z27*AA27/X27))/$M$21 -> 0 | AJ27: Fuel Oil | AL27: COA | AM27: =D77/1000 -> 0 | AN27: =AM27*$AN$23 -> 0 | AO27: =AM27*$AO$23 -> 0 | AP27: =AM27*$AP$23 -> 0 | AQ27: =IFERROR(G27*$Z27*$AA27/G$21,0) -> 0 | AR27: =IFERROR(H27*$Z27*$AA27/H$21,0) -> 0 | AS27: =IFERROR(I27*$Z27*$AA27/I$21,0) -> 0 | AT27: =IFERROR(AQ27/W27,0) -> 0 | AU27: =IFERROR(AR27/X27,0) -> 0 | AV27: =IFERROR(AS27/Y27,0) -> 0 | AY27: COA | AZ27: =D102/1000 -> 0 | BA27: =DE27*$AN$23 -> 0 | BB27: =DE27*$BB$23 -> 0 | BC27: =DE27*$BC$23 -> 0 | BD27: =IFERROR(J27*$Z27*AA27/J$21,0) -> 0 | BE27: =IFERROR(K27*$Z27*AA27/K$21,0) -> 0 | BF27: =IFERROR(L27*$Z27*AB27/L$21,0) -> 0 | BG27: =IFERROR(BD27/W27,0) -> 0 | BH27: =IFERROR(BE27/X27,0) -> 0 | BI27: =IFERROR(BF27/Y27,0) -> 0 | BL27: COA | BM27: =D127/1000 -> 0 | BN27: =BM27*$AN$23 -> 0 | BO27: =BM27*$BB$23 -> 0 | BP27: =BM27*$BC$23 -> 0 | BQ27: =IFERROR(M27*$Z27*$AA27/M$21,0) -> 0 | BR27: =IFERROR(N27*$Z27*$AA27/N$21,0) -> 0 | BS27: =IFERROR(O27*$Z27*$AA27/O$21,0) -> 0 | BT27: =IFERROR(BQ27/W27,0) -> 0 | BU27: =IFERROR(BR27/X27,0) -> 0 | BV27: =IFERROR(BS27/Y27,0) -> 0
C28: =+IF(OFFSET(Processes!B9,$D$11,0)="*","*",OFFSET(Processes!D9,$D$11,0)) -> AGRPHBDSLE1 | D28: =+OFFSET(Processes!E9,$D$11,0) -> Agriculture Heat Medium Temp. Boiler - Diesel Existing 1 | E28: =+Processes!O9 -> AGRDSB1,AGRDSB2,AGRDSL | F28: =Commodities!$D$6 -> AGDPH | G28: =AN28/($Z28*$AA28)*G$21*W28 -> 0 | H28: =AO28/($Z28*$AA28)*H$21*X28 -> 0 | I28: =AP28/($Z28*$AA28)*I$21*Y28 -> 0 | J28: =BA28/($Z28*$AA28)*J$21*W28 -> 0 | K28: =BB28/($Z28*$AA28)*K$21*X28 -> 0 | L28: =BC28/($Z28*$AA28)*L$21*Y28 -> 0 | M28: =BN28/($Z28*$AA28)*M$21*W28 -> 0 | N28: =BO28/($Z28*$AA28)*N$21*X28 -> 0 | O28: =BP28/($Z28*$AA28)*O$21*Y28 -> 0 | P28: =M28 -> 0 | Q28: =N28 -> 0 | R28: =O28 -> 0 | S28: =IF($AB28=20,0,M28/5)*IF(M28=0,0,1) -> 0 | T28: =IF($AB28=20,0,N28/5)*IF(N28=0,0,1) -> 0 | U28: =IF($AB28=20,0,O28/5)*IF(O28=0,0,1) -> 0 | V28: 5 | W28: =F146 -> 0.9408 | X28: =W28 -> 0.9408 | Y28: =X28 -> 0.9408 | Z28: =3.6*8760/1000000 -> 0.031536 | AA28: =$AA$26 -> 0.5 | AB28: 20 | AG28: =((G28*Z28*AA28/W28)+(H28*Z28*AA28/X28))/$G$21 -> 0 | AH28: =((J28*Z28*AA28/W28)+(K28*Z28*AA28/X28))/$J$21 -> 0 | AI28: =((M28*AA28*Z28/W28)+(N28*Z28*AA28/X28))/$M$21 -> 0 | AJ28: Diesel | AL28: DSL | AM28: =(F77+L77)/1000 -> 0 | AN28: =AM28*$AN$23 -> 0 | AO28: =AM28*$AO$23 -> 0 | AP28: =AM28*$AP$23 -> 0 | AQ28: =IFERROR(G28*$Z28*$AA28/G$21,0) -> 0 | AR28: =IFERROR(H28*$Z28*$AA28/H$21,0) -> 0 | AS28: =IFERROR(I28*$Z28*$AA28/I$21,0) -> 0 | AT28: =IFERROR(AQ28/W28,0) -> 0 | AU28: =IFERROR(AR28/X28,0) -> 0 | AV28: =IFERROR(AS28/Y28,0) -> 0 | AY28: DSL | AZ28: =(F102+L102)/1000 -> 0 | BA28: =DE28*$AN$23 -> 0 | BB28: =DE28*$BB$23 -> 0 | BC28: =DE28*$BC$23 -> 0 | BD28: =IFERROR(J28*$Z28*AA28/J$21,0) -> 0 | BE28: =IFERROR(K28*$Z28*AA28/K$21,0) -> 0 | BF28: =IFERROR(L28*$Z28*AA28/L$21,0) -> 0 | BG28: =IFERROR(BD28/W28,0) -> 0 | BH28: =IFERROR(BE28/X28,0) -> 0 | BI28: =IFERROR(BF28/Y28,0) -> 0 | BL28: DSL | BM28: =(F127+L127)/1000 -> 0 | BN28: =BM28*$AN$23 -> 0 | BO28: =BM28*$BB$23 -> 0 | BP28: =BM28*$BC$23 -> 0 | BQ28: =IFERROR(M28*$Z28*$AA28/M$21,0) -> 0 | BR28: =IFERROR(N28*$Z28*$AA28/N$21,0) -> 0 | BS28: =IFERROR(O28*$Z28*$AA28/O$21,0) -> 0 | BT28: =IFERROR(BQ28/W28,0) -> 0 | BU28: =IFERROR(BR28/X28,0) -> 0 | BV28: =IFERROR(BS28/Y28,0) -> 0
C29: =+IF(OFFSET(Processes!B10,$D$11,0)="*","*",OFFSET(Processes!D10,$D$11,0)) -> AGRPHBWPEE1 | D29: =+OFFSET(Processes!E10,$D$11,0) -> Agriculture Heat Medium Temp. Boiler - Wood Pellets Existing 1 | E29: =+Processes!O10 -> AGRWPE | F29: =Commodities!$D$6 -> AGDPH | G29: =AN29/($Z29*$AA29)*G$21*W29 -> 288.57348 | H29: =AO29/($Z29*$AA29)*H$21*X29 -> 0 | I29: =AP29/($Z29*$AA29)*I$21*Y29 -> 0 | J29: =BA29/($Z29*$AA29)*J$21*W29 -> 0 | K29: =BB29/($Z29*$AA29)*K$21*X29 -> 0 | L29: =BC29/($Z29*$AA29)*L$21*Y29 -> 0 | M29: =BN29/($Z29*$AA29)*M$21*W29 -> 226.33954 | N29: =BO29/($Z29*$AA29)*N$21*X29 -> 0 | O29: =BP29/($Z29*$AA29)*O$21*Y29 -> 0 | P29: =M29 -> 226.33954 | Q29: =N29 -> 0 | R29: =O29 -> 0 | S29: =IF($AB29=20,0,M29/5)*IF(M29=0,0,1) -> 0 | T29: =IF($AB29=20,0,N29/5)*IF(N29=0,0,1) -> 0 | U29: =IF($AB29=20,0,O29/5)*IF(O29=0,0,1) -> 0 | V29: 5 | W29: =$K$146 -> 0.833 | X29: =$W$29 -> 0.833 | Y29: =$W$29 -> 0.833 | Z29: =3.6*8760/1000000 -> 0.031536 | AA29: =$AA$26 -> 0.5 | AB29: 20 | AC29: 0.5 | AD29: 0.5 | AE29: 5 | AG29: =((G29*Z29*AA29/W29)+(H29*Z29*AA29/X29))/$G$21 -> 5.457 | AH29: =((J29*Z29*AA29/W29)+(K29*Z29*AA29/X29))/$J$21 -> 0 | AI29: =((M29*AA29*Z29/W29)+(N29*Z29*AA29/X29))/$M$21 -> 4.242 | AJ29: Gasoline | AL29: WPE | AM29: =M77/1000 -> 5.457 | AN29: =AM29*$AN$23 -> 5.457 | AO29: =AM29*$AO$23 -> 0 | AP29: =AM29*$AP$23 -> 0 | AQ29: =IFERROR(G29*$Z29*$AA29/G$21,0) -> 4.545681 | AR29: =IFERROR(H29*$Z29*$AA29/H$21,0) -> 0 | AS29: =IFERROR(I29*$Z29*$AA29/I$21,0) -> 0 | AT29: =IFERROR(AQ29/W29,0) -> 5.457 | AU29: =IFERROR(AR29/X29,0) -> 0 | AV29: =IFERROR(AS29/Y29,0) -> 0 | AY29: WPE | AZ29: =M102/1000 -> 4.379 | BA29: =DE29*$AN$23 -> 0 | BB29: =DE29*$BB$23 -> 0 | BC29: =DE29*$BC$23 -> 0 | BD29: =IFERROR(J29*$Z29*AA29/J$21,0) -> 0 | BE29: =IFERROR(K29*$Z29*AA29/K$21,0) -> 0 | BF29: =IFERROR(L29*$Z29*AB29/L$21,0) -> 0 | BG29: =IFERROR(BD29/W29,0) -> 0 | BH29: =IFERROR(BE29/X29,0) -> 0 | BI29: =IFERROR(BF29/Y29,0) -> 0 | BL29: WPE | BM29: =M127/1000 -> 4.242 | BN29: =BM29*$AN$23 -> 4.242 | BO29: =BM29*$BB$23 -> 0 | BP29: =BM29*$BC$23 -> 0 | BQ29: =IFERROR(M29*$Z29*$AA29/M$21,0) -> 3.533586 | BR29: =IFERROR(N29*$Z29*$AA29/N$21,0) -> 0 | BS29: =IFERROR(O29*$Z29*$AA29/O$21,0) -> 0 | BT29: =IFERROR(BQ29/W29,0) -> 4.242 | BU29: =IFERROR(BR29/X29,0) -> 0 | BV29: =IFERROR(BS29/Y29,0) -> 0
E30: =+Processes!O11 -> AGRWCH | P30: =M30 -> 0 | Q30: =N30 -> 0 | R30: =O30 -> 0 | S30: =IF($AB30=20,0,M30/5)*IF(M30=0,0,1) -> 0 | T30: =IF($AB30=20,0,N30/5)*IF(N30=0,0,1) -> 0 | U30: =IF($AB30=20,0,O30/5)*IF(O30=0,0,1) -> 0 | V30: =IF(S30>0,0.001,"") | W30: =$K$146 -> 0.833 | X30: =$W$29 -> 0.833 | Y30: =$W$29 -> 0.833 | AC30: =1-AC29 -> 0.5 | AD30: =1-AD29 -> 0.5 | AE30: 5 | AG30: =((G30*Z30*AA30/W30)+(H30*Z30*AA30/X30))/$G$21 -> 0 | AH30: =((J30*Z30*AA30/W30)+(K30*Z30*AA30/X30))/$J$21 -> 0 | AI30: =((M30*AA30*Z30/W30)+(N30*Z30*AA30/X30))/$M$21 -> 0 | AJ30: LPG | AL30: WCH | AQ30: =IFERROR(G30*$Z30*$AA30/G$21,0) -> 0 | AR30: =IFERROR(H30*$Z30*$AA30/H$21,0) -> 0 | AS30: =IFERROR(I30*$Z30*$AA30/I$21,0) -> 0 | AY30: WCH | BD30: =IFERROR(J30*$Z30*AA30/J$21,0) -> 0 | BE30: =IFERROR(K30*$Z30*AA30/K$21,0) -> 0 | BF30: =IFERROR(L30*$Z30*AB30/L$21,0) -> 0 | BG30: =IFERROR(BD30/W30,0) -> 0 | BH30: =IFERROR(BE30/X30,0) -> 0 | BI30: =IFERROR(BF30/Y30,0) -> 0 | BL30: WCH | BQ30: =IFERROR(M30*$Z30*$AA30/M$21,0) -> 0 | BR30: =IFERROR(N30*$Z30*$AA30/N$21,0) -> 0 | BS30: =IFERROR(O30*$Z30*$AA30/O$21,0) -> 0 | BT30: =IFERROR(BQ30/W30,0) -> 0 | BU30: =IFERROR(BR30/X30,0) -> 0 | BV30: =IFERROR(BS30/Y30,0) -> 0
C31: =+IF(OFFSET(Processes!B12,$D$11,0)="*","*",OFFSET(Processes!D12,$D$11,0)) -> AGRPHBBGAE1 | D31: =+OFFSET(Processes!E12,$D$11,0) -> Agriculture Heat Medium Temp. Boiler - Biogas Existing 1 | E31: =+Processes!O12 -> AGRBGA | F31: =Commodities!$D$6 -> AGDPH | G31: =AN31/($Z31*$AA31)*G$21*W31 -> 752.86109 | H31: =AO31/($Z31*$AA31)*H$21*X31 -> 0 | I31: =AP31/($Z31*$AA31)*I$21*Y31 -> 0 | J31: =BA31/($Z31*$AA31)*J$21*W31 -> 0 | K31: =BB31/($Z31*$AA31)*K$21*X31 -> 0 | L31: =BC31/($Z31*$AA31)*L$21*Y31 -> 0 | M31: =BN31/($Z31*$AA31)*M$21*W31 -> 1502.997 | N31: =BO31/($Z31*$AA31)*N$21*X31 -> 0 | O31: =BP31/($Z31*$AA31)*O$21*Y31 -> 0 | P31: =M31 -> 1502.997 | Q31: =N31 -> 0 | R31: =O31 -> 0 | S31: =IF($AB31=20,0,M31/5)*IF(M31=0,0,1) -> 0 | T31: =IF($AB31=20,0,N31/5)*IF(N31=0,0,1) -> 0 | U31: =IF($AB31=20,0,O31/5)*IF(O31=0,0,1) -> 0 | V31: 5 | W31: =J146 -> 0.9996 | X31: =W31 -> 0.9996 | Y31: =X31 -> 0.9996 | Z31: =3.6*8760/1000000 -> 0.031536 | AA31: =$AA$26 -> 0.5 | AB31: 20 | AG31: =((G31*Z31*AA31/W31)+(H31*Z31*AA31/X31))/$G$21 -> 11.864 | AH31: =((J31*Z31*AA31/W31)+(K31*Z31*AA31/X31))/$J$21 -> 0 | AI31: =((M31*AA31*Z31/W31)+(N31*Z31*AA31/X31))/$M$21 -> 23.474 | AJ31: Manufactured gases | AL31: BGA | AM31: =K77/1000 -> 11.864 | AN31: =AM31*$AN$23 -> 11.864 | AO31: =AM31*$AO$23 -> 0 | AP31: =AM31*$AP$23 -> 0 | AQ31: =IFERROR(G31*$Z31*$AA31/G$21,0) -> 11.859254 | AR31: =IFERROR(H31*$Z31*$AA31/H$21,0) -> 0 | AS31: =IFERROR(I31*$Z31*$AA31/I$21,0) -> 0 | AT31: =IFERROR(AQ31/W31,0) -> 11.864 | AU31: =IFERROR(AR31/X31,0) -> 0 | AV31: =IFERROR(AS31/Y31,0) -> 0 | AY31: BGA | AZ31: =K102/1000 -> 22.744 | BA31: =DE31*$AN$23 -> 0 | BB31: =DE31*$BB$23 -> 0 | BC31: =DE31*$BC$23 -> 0 | BD31: =IFERROR(J31*$Z31*AA31/J$21,0) -> 0 | BE31: =IFERROR(K31*$Z31*AA31/K$21,0) -> 0 | BF31: =IFERROR(L31*$Z31*AB31/L$21,0) -> 0 | BG31: =IFERROR(BD31/W31,0) -> 0 | BH31: =IFERROR(BE31/X31,0) -> 0 | BI31: =IFERROR(BF31/Y31,0) -> 0 | BL31: BGA | BM31: =K127/1000 -> 23.474 | BN31: =BM31*$AN$23 -> 23.474 | BO31: =BM31*$BB$23 -> 0 | BP31: =BM31*$BC$23 -> 0 | BQ31: =IFERROR(M31*$Z31*$AA31/M$21,0) -> 23.46461 | BR31: =IFERROR(N31*$Z31*$AA31/N$21,0) -> 0 | BS31: =IFERROR(O31*$Z31*$AA31/O$21,0) -> 0 | BT31: =IFERROR(BQ31/W31,0) -> 23.474 | BU31: =IFERROR(BR31/X31,0) -> 0 | BV31: =IFERROR(BS31/Y31,0) -> 0
C32: =+IF(OFFSET(Processes!B13,$D$11,0)="*","*",OFFSET(Processes!D13,$D$11,0)) -> AGRPHBHFOE1 | D32: =+OFFSET(Processes!E13,$D$11,0) -> Agriculture Heat Medium Temp. Boiler - Heavy Fuel Oil Existing 1 | E32: =+Processes!O13 -> AGRHFO | F32: =Commodities!$D$6 -> AGDPH | G32: =AN32/($Z32*$AA32)*G$21*W32 -> 0 | H32: =AO32/($Z32*$AA32)*H$21*X32 -> 0 | I32: =AP32/($Z32*$AA32)*I$21*Y32 -> 0 | J32: =BA32/($Z32*$AA32)*J$21*W32 -> 0 | K32: =BB32/($Z32*$AA32)*K$21*X32 -> 0 | L32: =BC32/($Z32*$AA32)*L$21*Y32 -> 0 | M32: =BN32/($Z32*$AA32)*M$21*W32 -> 0 | N32: =BO32/($Z32*$AA32)*N$21*X32 -> 0 | O32: =BP32/($Z32*$AA32)*O$21*Y32 -> 0 | P32: =M32 -> 0 | Q32: =N32 -> 0 | R32: =O32 -> 0 | S32: =IF($AB32=20,0,M32/5)*IF(M32=0,0,1) -> 0 | T32: =IF($AB32=20,0,N32/5)*IF(N32=0,0,1) -> 0 | U32: =IF($AB32=20,0,O32/5)*IF(O32=0,0,1) -> 0 | V32: 5 | W32: =E146 -> 0.931 | X32: =W32 -> 0.931 | Y32: =X32 -> 0.931 | Z32: =3.6*8760/1000000 -> 0.031536 | AA32: =$AA$26 -> 0.5 | AB32: 20 | AG32: =((G32*Z32*AA32/W32)+(H32*Z32*AA32/X32))/$G$21 -> 0 | AH32: =((J32*Z32*AA32/W32)+(K32*Z32*AA32/X32))/$J$21 -> 0 | AI32: =((M32*AA32*Z32/W32)+(N32*Z32*AA32/X32))/$M$21 -> 0 | AJ32: Natural gas | AL32: HFO | AM32: =E77/1000 -> 0 | AN32: =AM32*$AN$23 -> 0 | AO32: =AM32*$AO$23 -> 0 | AP32: =AM32*$AP$23 -> 0 | AQ32: =IFERROR(G32*$Z32*$AA32/G$21,0) -> 0 | AR32: =IFERROR(H32*$Z32*$AA32/H$21,0) -> 0 | AS32: =IFERROR(I32*$Z32*$AA32/I$21,0) -> 0 | AT32: =IFERROR(AQ32/W32,0) -> 0 | AU32: =IFERROR(AR32/X32,0) -> 0 | AV32: =IFERROR(AS32/Y32,0) -> 0 | AY32: HFO | AZ32: =E102/1000 -> 0 | BA32: =DE32*$AN$23 -> 0 | BB32: =DE32*$BB$23 -> 0 | BC32: =DE32*$BC$23 -> 0 | BD32: =IFERROR(J32*$Z32*AA32/J$21,0) -> 0 | BE32: =IFERROR(K32*$Z32*AA32/K$21,0) -> 0 | BF32: =IFERROR(L32*$Z32*AA32/L$21,0) -> 0 | BG32: =IFERROR(BD32/W32,0) -> 0 | BH32: =IFERROR(BE32/X32,0) -> 0 | BI32: =IFERROR(BF32/Y32,0) -> 0 | BL32: HFO | BM32: =E127/1000 -> 0 | BN32: =BM32*$AN$23 -> 0 | BO32: =BM32*$BB$23 -> 0 | BP32: =BM32*$BC$23 -> 0 | BQ32: =IFERROR(M32*$Z32*$AA32/M$21,0) -> 0 | BR32: =IFERROR(N32*$Z32*$AA32/N$21,0) -> 0 | BS32: =IFERROR(O32*$Z32*$AA32/O$21,0) -> 0 | BT32: =IFERROR(BQ32/W32,0) -> 0 | BU32: =IFERROR(BR32/X32,0) -> 0 | BV32: =IFERROR(BS32/Y32,0) -> 0
