Workbook
Name _bgvbyrgdt: [1]Tidsserier!$A$339:$IV$339
Name _bgvbyrlpg: [1]Tidsserier!$A$337:$IV$337
Name _bgvbyrlvn: [1]Tidsserier!$A$338:$IV$338
Name _bgvbyrnga: [1]Tidsserier!$A$340:$IV$340
Name _bgvbyrrga: [1]Tidsserier!$A$336:$IV$336
Name _bgvbyrska: [1]Tidsserier!$A$341:$IV$341
Name _celelrfut: [1]Tidsserier!$A$174:$IV$174
Name _celelrgdt: [1]Tidsserier!$A$173:$IV$173
Name _celelrhal: [1]Tidsserier!$A$176:$IV$176
Name _celelrske: [1]Tidsserier!$A$175:$IV$175
Name _cevelraff: [1]Tidsserier!$A$197:$IV$197
Name _cevelrbio: [1]Tidsserier!$A$196:$IV$196
Name _cevelrfli: [1]Tidsserier!$A$193:$IV$193
Name _cevelrfut: [1]Tidsserier!$A$187:$IV$187
Name _cevelrgdt: [1]Tidsserier!$A$186:$IV$186
Name _cevelrhal: [1]Tidsserier!$A$192:$IV$192
Name _cevelrlpg: [1]Tidsserier!$A$184:$IV$184
Name _cevelrlvn: [1]Tidsserier!$A$185:$IV$185
Name _cevelrnga: [1]Tidsserier!$A$190:$IV$190
Name _cevelrori: [1]Tidsserier!$A$189:$IV$189
Name _cevelrpko: [1]Tidsserier!$A$188:$IV$188
Name _cevelrrga: [1]Tidsserier!$A$183:$IV$183
Name _cevelrske: [1]Tidsserier!$A$191:$IV$191
Name _cevelrtaf: [1]Tidsserier!$A$195:$IV$195
Name _cevfjraff: [1]Tidsserier!$A$213:$IV$213
Name _cevfjrbio: [1]Tidsserier!$A$212:$IV$212
Name _cevfjrfli: [1]Tidsserier!$A$209:$IV$209
Name _cevfjrfut: [1]Tidsserier!$A$203:$IV$203
Name _cevfjrgdt: [1]Tidsserier!$A$202:$IV$202
Name _cevfjrhal: [1]Tidsserier!$A$208:$IV$208
Name _cevfjrlpg: [1]Tidsserier!$A$200:$IV$200
Name _cevfjrlvn: [1]Tidsserier!$A$201:$IV$201
Name _cevfjrnga: [1]Tidsserier!$A$206:$IV$206
Name _cevfjrori: [1]Tidsserier!$A$205:$IV$205
Name _cevfjrpko: [1]Tidsserier!$A$204:$IV$204
Name _cevfjrrga: [1]Tidsserier!$A$199:$IV$199
Name _cevfjrske: [1]Tidsserier!$A$207:$IV$207
Name _cevfjrtaf: [1]Tidsserier!$A$211:$IV$211
Name _cevfjrtpi: [1]Tidsserier!$A$210:$IV$210
Name _dnkexpelc: [1]Tidsserier!$A$69:$IV$69
Name _dnkexpnga: [1]Tidsserier!$A$68:$IV$68
Name _dnkexprao: [1]Tidsserier!$A$52:$IV$52
Name _dnkimpelc: [1]Tidsserier!$A$45:$IV$45
Name _dnkimpfjv: [1]Tidsserier!$A$46:$IV$46
Name _dnkudvaff: [1]Tidsserier!$A$17:$IV$17
Name _dnkudvbio: [1]Tidsserier!$A$16:$IV$16
Name _dnkudvbra: [1]Tidsserier!$A$13:$IV$13
Name _dnkudvfio: [1]Tidsserier!$A$18:$IV$18
Name _dnkudvfli: [1]Tidsserier!$A$12:$IV$12
Name _dnkudvgeo: [1]Tidsserier!$A$10:$IV$10
Name _dnkudvhal: [1]Tidsserier!$A$11:$IV$11
Name _dnkudvsol: [1]Tidsserier!$A$7:$IV$7
Name _dnkudvtaf: [1]Tidsserier!$A$15:$IV$15
Name _dnkudvtpi: [1]Tidsserier!$A$14:$IV$14
Name _dnkudvvan: [1]Tidsserier!$A$9:$IV$9
Name _dnkudvvin: [1]Tidsserier!$A$8:$IV$8
Name _dnkudvvmp: [1]Tidsserier!$A$19:$IV$19
Name _ensdstelc: [1]Tidsserier!$A$348:$IV$348
Name _enstabfjv: [1]Tidsserier!$A$352:$IV$352
Name _enstabnga: [1]Tidsserier!$A$350:$IV$350

Sheet LOG
A1: Selects cells and the then Ctrl+shift+L to add entries
A3: Date | B3: Name | C3: Sheet Name | D3: Cell no
A4: 44297 | B4: Mikkel Bosack Simonsen | C4: All | E4: Based on the ONTIMES model a structure has been developed for the TIMES-AZ model.
A5: 44298 | B5: Mikkel Bosack Simonsen | C5: All | E5: Removed all Norwegian dataset and implemented Azabaijanian energy statistics, allthough service demand split is used based on WMAS study in Denmark. Expected to be changed for heavy industri

Sheet Intro
B1: Description
B3: Purpose: | C3: This sheet defines processes, commodities and existing stocks for industies energy services
B4: Description: | C4: The data is based on the VMAS survey of energy services as well as the energy matrices from Statistics Denmark
B6: Relevant sectors | C6: IND
B8: Description of different sheets
B10: Processes | C10: Defines the processes for each sector
B11: Commodities | C11: Defines the commodities used in the processes
B12: Demand | C12: Benchmark demand for energy services for all industries 2010
B13: IronSteel | C13: Topology for processes and commodities used in Agriculture
B14: Chemical | C14: Topology for processes and commodities used in Food
B15: Aluminium | C15: Topology for processes and commodities used in Chemical
B16: GlassConcrete | C16: Topology for processes and commodities used in Glass&Concrete
B17: Transport | C17: Topology for processes and commodities used in Metal
B18: Machinery | C18: Topology for processes and commodities used in Other
B19: Mining | C19: Topology for processes and commodities used in Motor Vehicles
B20: Food | C20: Topology for processes and commodities used in Sales
B21: PulpPaper | C21: Topology for processes and commodities used in PrivateServices
... B28: Energy Matrix | C28: Energy matrix from Statistics Denmark 2010
B29: 2010 | C29: =B29&" Energy statistics of Azerbaijan" -> 2010 Energy statistics of Azerbaijan
B30: 2015 | C30: =B30&" Energy statistics of Azerbaijan" -> 2015 Energy statistics of Azerbaijan
B31: 2019 | C31: =B31&" Energy statistics of Azerbaijan" -> 2019 Energy statistics of Azerbaijan

Sheet Processes
B4: ~FI_Process | R4: Text to associate with Tech Names:
B5: Sets | C5: Region | D5: TechName | E5: TechDesc | F5: Tact | G5: Tcap | H5: Tslvl | I5: PrimaryCG | J5: Vintage | R5: - and in column R a one letter code to be used in Tech Name.
B6: *Process Set Membership | C6: Region Name | D6: Technology Name | E6: Technology Description | F6: Activity Unit | G6: Capacity Unit | H6: TimeSlice level of Process Activity | I6: Primary Commodity Group | J6: Vintage Tracking | O6: Comm-IN | P6: Comm-OUT | R6: This colour: Input
B7: DMD | D7: =M13 & P$7 & R$7 & VLOOKUP(O$7, $O$50:$P$74,2,FALSE) & "E1" -> INDSDPHBNGAE1 | E7: =+M10 & " " & S$7 & " - " & T$7 & " " & U$7 -> Iron & Steel Heat Medium Temp. Boiler - Nat. Gas Existing 1 | F7: PJ | G7: MW | L7: Index: 1 - 9 | M7: 1 | O7: =Commodities!$D$113&","&Commodities!$D$114&","&Commodities!$D$97 -> INDSNG1,INDSNG2,INDNGA | P7: =+Commodities!$AL$6 -> DPH | R7: B | S7: Heat Medium Temp. Boiler | T7: Nat. Gas | U7: Existing 1
B8: =+IF(ISBLANK(D8),"*","") | D8: =M13 & P$8 & R$8 & VLOOKUP(O$8, $O$50:$P$74,2,FALSE) & "E1" -> INDSDPHBCOAE1 | E8: =+M10 & " " & S$8 & " - " & T$8 & " " & U$8 -> Iron & Steel Heat Medium Temp. Boiler - Coal Existing 1 | F8: PJ | G8: MW | O8: =Commodities!$D$98 -> INDCOA | P8: =+Commodities!$AL$6 -> DPH | R8: =+R$7 -> B | S8: =+S$7 -> Heat Medium Temp. Boiler | T8: Coal | U8: =+U$7 -> Existing 1
B9: =+IF(ISBLANK(D9),"*","") | D9: =M13 & P$9 & R$9 & VLOOKUP(O$9, $O$50:$P$74,2,FALSE) & "E1" -> INDSDPHBDSLE1 | E9: =+M10 & " " & S$9 & " - " & T$9 & " " & U$9 -> Iron & Steel Heat Medium Temp. Boiler - Diesel Existing 1 | F9: PJ | G9: MW | L9: Sheet: | M9: Commodities | O9: =Commodities!$D$111&","&Commodities!$D$112&","&Commodities!$D$99 -> INDDSB1,INDDSB2,INDDSL | P9: =+Commodities!$AL$6 -> DPH | R9: =+R$7 -> B | S9: =+S$7 -> Heat Medium Temp. Boiler | T9: Diesel | U9: =+U$7 -> Existing 1
B10: =+IF(ISBLANK(D10),"*","") | D10: =M13 & P$10 & R$10 & VLOOKUP(O$10, $O$50:$P$74,2,FALSE) & "E1" -> INDSDPHBWPEE1 | E10: =+M10 & " " & S$10 & " - " & T$10 & " " & U$10 -> Iron & Steel Heat Medium Temp. Boiler - Wood Pellets Existing 1 | F10: PJ | G10: MW | L10: Sector: | M10: =+INDEX(Commodities!$X$6:$X$17,M7) -> Iron & Steel | O10: =Commodities!$D$100 -> INDWPE | P10: =+Commodities!$AL$6 -> DPH | R10: =+R$7 -> B | S10: =+S$7 -> Heat Medium Temp. Boiler | T10: Wood Pellets | U10: =+U$7 -> Existing 1
B11: =+IF(ISBLANK(D11),"*","") -> * | M11: =+INDEX(Commodities!$Y$6:$Y$17,M7) -> 01 Iron and steel | O11: =Commodities!$D$101 -> INDWCH
B12: =+IF(ISBLANK(D12),"*","") | D12: =M13 & P$12 & R$12 & VLOOKUP(O$12, $O$50:$P$74,2,FALSE) & "E1" -> INDSDPHBBGAE1 | E12: =+M10 & " " & S$12 & " - " & T$12 & " " & U$12 -> Iron & Steel Heat Medium Temp. Boiler - Biogas Existing 1 | F12: PJ | G12: MW | L12: Code: | M12: =+INDEX(Commodities!$U$6:$U$17,M7) -> IS | O12: =Commodities!$D$102 -> INDBGA | P12: =+Commodities!$AL$6 -> DPH | R12: =+R$7 -> B | S12: =+S$7 -> Heat Medium Temp. Boiler | T12: Biogas | U12: =+U$7 -> Existing 1
B13: =+IF(ISBLANK(D13),"*","") | D13: =M13 & P$13 & R$13 & VLOOKUP(O$13, $O$50:$P$74,2,FALSE) & "E1" -> INDSDPHBHFOE1 | E13: =+M10 & " " & S$13 & " - " & T$13 & " " & U$13 -> Iron & Steel Heat Medium Temp. Boiler - Heavy Fuel Oil Existing 1 | F13: PJ | G13: MW | L13: Code: | M13: =+INDEX(Commodities!$W$6:$W$17,M7) -> INDS | O13: =Commodities!$D$103 -> INDHFO | P13: =+Commodities!$AL$6 -> DPH | R13: =+R$7 -> B | S13: =+S$7 -> Heat Medium Temp. Boiler | T13: Heavy Fuel Oil | U13: =+U$7 -> Existing 1
B14: =+IF(ISBLANK(D14),"*","") | D14: =M13 & P$14 & R$14 & VLOOKUP(O$14, $O$50:$P$74,2,FALSE) & "E1" -> INDSDPHBLPGE1 | E14: =+M10 & " " & S$14 & " - " & T$14 & " " & U$14 -> Iron & Steel Heat Medium Temp. Boiler - Liquified Petroleum Gas Existing 1 | F14: PJ | G14: MW | O14: =Commodities!$D$104 -> INDLPG | P14: =+Commodities!$AL$6 -> DPH | R14: =+R$7 -> B | S14: =+S$7 -> Heat Medium Temp. Boiler | T14: Liquified Petroleum Gas | U14: =+U$7 -> Existing 1
B15: =+IF(ISBLANK(D15),"*","") | D15: =M13 & P$15 & R$15 & VLOOKUP(O$15, $O$50:$P$74,2,FALSE) & "E1" -> INDSDPHBWSTE1 | E15: =+M10 & " " & S$15 & " - " & T$15 & " " & U$15 -> Iron & Steel Heat Medium Temp. Boiler - Waste Existing 1 | F15: PJ | G15: MW | O15: =Commodities!$D$105 -> INDWST | P15: =+Commodities!$AL$6 -> DPH | R15: =+R$7 -> B | S15: =+S$7 -> Heat Medium Temp. Boiler | T15: Waste | U15: =+U$7 -> Existing 1
B16: =+IF(ISBLANK(D16),"*","") | D16: =M13 & P$16 & R$16 & VLOOKUP(O$16, $O$50:$P$74,2,FALSE) & "E1" -> INDSDPHBHETE1 | E16: =+M10 & " " & S$16 & " - " & T$16 & " " & U$16 -> Iron & Steel Heat Medium Temp. Boiler - Dist. Heat Existing 1 | F16: PJ | G16: MW | O16: =Commodities!$D$106 -> INDHCE | P16: =+Commodities!$AL$6 -> DPH | R16: =+R$7 -> B | S16: =+S$7 -> Heat Medium Temp. Boiler | T16: Dist. Heat | U16: =+U$7 -> Existing 1
B17: =+IF(ISBLANK(D17),"*","") | D17: =M13 & P$17 & R$17 & VLOOKUP(O$17, $O$50:$P$74,2,FALSE) & "E2" -> INDSDPHBHETE2 | E17: =+M10 & " " & S$17 & " - " & T$17 & " " & U$17 -> Iron & Steel Heat Medium Temp. Boiler - Dist. Heat Existing 2 | F17: PJ | G17: MW | O17: =Commodities!$D$108 -> INDHDE | P17: DPH | R17: B | S17: =+S$7 -> Heat Medium Temp. Boiler | T17: Dist. Heat | U17: Existing 2
B18: =+IF(ISBLANK(D18),"*","") | D18: =M13 & P$18 & R$18 & VLOOKUP(O$18, $O$50:$P$74,2,FALSE) & "E1" -> INDSDPHBELCE1 | E18: =+M10 & " " & S$18 & " - " & T$18 & " " & U$18 -> Iron & Steel Heat Medium Temp. Boiler - Electricity Existing 1 | F18: PJ | G18: MW | O18: =Commodities!$D$109 -> INDELC | P18: =+Commodities!$AL$6 -> DPH | R18: =+R$7 -> B | S18: =+S$7 -> Heat Medium Temp. Boiler | T18: Electricity | U18: =+U$7 -> Existing 1
B19: =+IF(ISBLANK(D19),"*","") | D19: =M13 & P$19 & R$19 & VLOOKUP(O$19, $O$50:$P$74,2,FALSE) & "E1" -> INDSDCOBNGAE1 | E19: =+M10 & " " & S$19 & " - " & T$19 & " " & U$19 -> Iron & Steel Heat High Temp. Boiler - Nat. Gas Existing 1 | F19: PJ | G19: MW | O19: =Commodities!$D$113&","&Commodities!$D$114&","&Commodities!$D$97 -> INDSNG1,INDSNG2,INDNGA | P19: =+Commodities!$AL$7 -> DCO | R19: =+R$7 -> B | S19: Heat High Temp. Boiler | T19: =+T$7 -> Nat. Gas | U19: =+U$7 -> Existing 1
B20: =+IF(ISBLANK(D20),"*","") | D20: =M13 & P$20 & R$20 & VLOOKUP(O$20, $O$50:$P$74,2,FALSE) & "E1" -> INDSDCOBCOAE1 | E20: =+M10 & " " & S$20 & " - " & T$20 & " " & U$20 -> Iron & Steel Heat High Temp. Boiler - Coal Existing 1 | F20: PJ | G20: MW | O20: =Commodities!$D$98 -> INDCOA | P20: =+Commodities!$AL$7 -> DCO | R20: =+R$7 -> B | S20: =$S$19 -> Heat High Temp. Boiler | T20: Coal | U20: =+U$7 -> Existing 1
B21: =+IF(ISBLANK(D21),"*","") | D21: =M13 & P$21 & R$21 & VLOOKUP(O$21, $O$50:$P$74,2,FALSE) & "E1" -> INDSDCOBDSLE1 | E21: =+M10 & " " & S$21 & " - " & T$21 & " " & U$21 -> Iron & Steel Heat High Temp. Boiler - Diesel Existing 1 | F21: PJ | G21: MW | O21: =Commodities!$D$111&","&Commodities!$D$112&","&Commodities!$D$99 -> INDDSB1,INDDSB2,INDDSL | P21: =+Commodities!$AL$7 -> DCO | R21: =+R$7 -> B | S21: =$S$19 -> Heat High Temp. Boiler | T21: Diesel | U21: =+U$7 -> Existing 1
B22: =+IF(ISBLANK(D22),"*","") | D22: =M13 & P$22 & R$22 & VLOOKUP(O$22, $O$50:$P$74,2,FALSE) & "E1" -> INDSDCOBWPEE1 | E22: =+M10 & " " & S$22 & " - " & T$22 & " " & U$22 -> Iron & Steel Heat High Temp. Boiler - Wood Pellets Existing 1 | F22: PJ | G22: MW | O22: =Commodities!$D$100 -> INDWPE | P22: =+Commodities!$AL$7 -> DCO | R22: =+R$7 -> B | S22: =$S$19 -> Heat High Temp. Boiler | T22: Wood Pellets | U22: =+U$7 -> Existing 1
B23: =+IF(ISBLANK(D23),"*","") -> * | O23: =Commodities!$D$101 -> INDWCH
B24: =+IF(ISBLANK(D24),"*","") | D24: =M13 & P$24 & R$24 & VLOOKUP(O$24, $O$50:$P$74,2,FALSE) & "E1" -> INDSDCOBHFOE1 | E24: =+M10 & " " & S$24 & " - " & T$24 & " " & U$24 -> Iron & Steel Heat High Temp. Boiler - Heavy Fuel Oil Existing 1 | F24: PJ | G24: MW | O24: =Commodities!$D$103 -> INDHFO | P24: =+Commodities!$AL$7 -> DCO | R24: =+R$7 -> B | S24: =$S$19 -> Heat High Temp. Boiler | T24: Heavy Fuel Oil | U24: =+U$7 -> Existing 1
B25: =+IF(ISBLANK(D25),"*","") | D25: =M13 & P$25 & R$25 & VLOOKUP(O$25, $O$50:$P$74,2,FALSE) & "E1" -> INDSDCOBLPGE1 | E25: =+M10 & " " & S$25 & " - " & T$25 & " " & U$25 -> Iron & Steel Heat High Temp. Boiler - Liquified Petroleum Gas Existing 1 | F25: PJ | G25: MW | O25: =Commodities!$D$104 -> INDLPG | P25: =+Commodities!$AL$7 -> DCO | R25: =+R$7 -> B | S25: =$S$19 -> Heat High Temp. Boiler | T25: Liquified Petroleum Gas | U25: =+U$7 -> Existing 1
B26: =+IF(ISBLANK(D26),"*","") | D26: =M13 & P$26 & R$26 & VLOOKUP(O$26, $O$50:$P$74,2,FALSE) & "E1" -> INDSDCOBWSTE1 | E26: =+M10 & " " & S$26 & " - " & T$26 & " " & U$26 -> Iron & Steel Heat High Temp. Boiler - Waste Existing 1 | F26: PJ | G26: MW | O26: INDWST | P26: =+Commodities!$AL$7 -> DCO | R26: =+R$7 -> B | S26: =$S$19 -> Heat High Temp. Boiler | T26: Waste | U26: Existing 1
B27: =+IF(ISBLANK(D27),"*","") | D27: =M13 & P$27 & R$27 & VLOOKUP(O$27, $O$50:$P$74,2,FALSE) & "E1" -> INDSDCOBELCE1 | E27: =+M10 & " " & S$27 & " - " & T$27 & " " & U$27 -> Iron & Steel Heat High Temp. Boiler - Electricity Existing 1 | F27: PJ | G27: MW | O27: INDELC | P27: =+Commodities!$AL$7 -> DCO | R27: =+R$7 -> B | S27: =$S$19 -> Heat High Temp. Boiler | T27: Electricity | U27: Existing 1
B28: =+IF(ISBLANK(D28),"*","") | D28: =M13 & P$28 & R$28 & VLOOKUP(O$28, $O$50:$P$74,2,FALSE) & "E1" -> INDSDSHBNGAE1 | E28: =+M10 & " " & S$28 & " - " & T$28 & " " & U$28 -> Iron & Steel Heat Room Boiler - Nat. Gas Existing 1 | F28: PJ | G28: MW | O28: =Commodities!$D$113&","&Commodities!$D$114&","&Commodities!$D$97 -> INDSNG1,INDSNG2,INDNGA | P28: =+Commodities!$AL$8 -> DSH | R28: =+R$7 -> B | S28: Heat Room Boiler | T28: =+T7 -> Nat. Gas | U28: =+U$7 -> Existing 1
B29: =+IF(ISBLANK(D29),"*","") | D29: =M13 & P$29 & R$29 & VLOOKUP(O$29, $O$50:$P$74,2,FALSE) & "E1" -> INDSDSHBCOAE1 | E29: =+M10 & " " & S$29 & " - " & T$29 & " " & U$29 -> Iron & Steel Heat Room Boiler - Coal Existing 1 | F29: PJ | G29: MW | O29: =Commodities!$D$98 -> INDCOA | P29: =+Commodities!$AL$8 -> DSH | R29: =+R$7 -> B | S29: =+S$28 -> Heat Room Boiler | T29: =+T8 -> Coal | U29: =+U$7 -> Existing 1
B30: =+IF(ISBLANK(D30),"*","") | D30: =M13 & P$30 & R$30 & VLOOKUP(O$30, $O$50:$P$74,2,FALSE) & "E1" -> INDSDSHBDSLE1 | E30: =+M10 & " " & S$30 & " - " & T$30 & " " & U$30 -> Iron & Steel Heat Room Boiler - Diesel Existing 1 | F30: PJ | G30: MW | O30: =Commodities!$D$111&","&Commodities!$D$112&","&Commodities!$D$99 -> INDDSB1,INDDSB2,INDDSL | P30: =+Commodities!$AL$8 -> DSH | R30: =+R$7 -> B | S30: =+S$28 -> Heat Room Boiler | T30: =+T9 -> Diesel | U30: =+U$7 -> Existing 1
B31: =+IF(ISBLANK(D31),"*","") | D31: =M13 & P$31 & R$31 & VLOOKUP(O$31, $O$50:$P$74,2,FALSE) & "E1" -> INDSDSHBWPEE1 | E31: =+M10 & " " & S$31 & " - " & T$31 & " " & U$31 -> Iron & Steel Heat Room Boiler - Wood Pellets Existing 1 | F31: PJ | G31: MW | O31: =Commodities!$D$100 -> INDWPE | P31: =+Commodities!$AL$8 -> DSH | R31: =+R$7 -> B | S31: =+S$28 -> Heat Room Boiler | T31: =+T10 -> Wood Pellets | U31: =+U$7 -> Existing 1
B32: =+IF(ISBLANK(D32),"*","") -> * | O32: =Commodities!$D$101 -> INDWCH
B33: =+IF(ISBLANK(D33),"*","") | D33: =M13 & P$33 & R$33 & VLOOKUP(O$33, $O$50:$P$74,2,FALSE) & "E1" -> INDSDSHBBGAE1 | E33: =+M10 & " " & S$33 & " - " & T$33 & " " & U$33 -> Iron & Steel Heat Room Boiler - Biogas Existing 1 | F33: PJ | G33: MW | O33: =Commodities!$D$102 -> INDBGA | P33: =+Commodities!$AL$8 -> DSH | R33: =+R$7 -> B | S33: =+S$28 -> Heat Room Boiler | T33: =+T12 -> Biogas | U33: =+U$7 -> Existing 1
B34: =+IF(ISBLANK(D34),"*","") | D34: =M13 & P$34 & R$34 & VLOOKUP(O$34, $O$50:$P$74,2,FALSE) & "E1" -> INDSDSHBHFOE1 | E34: =+M10 & " " & S$34 & " - " & T$34 & " " & U$34 -> Iron & Steel Heat Room Boiler - Heavy Fuel Oil Existing 1 | F34: PJ | G34: MW | O34: =Commodities!$D$103 -> INDHFO | P34: =+Commodities!$AL$8 -> DSH | R34: =+R$7 -> B | S34: =+S$28 -> Heat Room Boiler | T34: =+T13 -> Heavy Fuel Oil | U34: =+U$7 -> Existing 1
B35: =+IF(ISBLANK(D35),"*","") | D35: =M13 & P$35 & R$35 & VLOOKUP(O$35, $O$50:$P$74,2,FALSE) & "E1" -> INDSDSHBLPGE1 | E35: =+M10 & " " & S$35 & " - " & T$35 & " " & U$35 -> Iron & Steel Heat Room Boiler - Liquified Petroleum Gas Existing 1 | F35: PJ | G35: MW | O35: =Commodities!$D$104 -> INDLPG | P35: =+Commodities!$AL$8 -> DSH | R35: =+R$7 -> B | S35: =+S$28 -> Heat Room Boiler | T35: =+T14 -> Liquified Petroleum Gas | U35: =+U$7 -> Existing 1
B36: =+IF(ISBLANK(D36),"*","") | D36: =M13 & P$36 & R$36 & VLOOKUP(O$36, $O$50:$P$74,2,FALSE) & "E1" -> INDSDSHBWSTE1 | E36: =+M10 & " " & S$36 & " - " & T$36 & " " & U$36 -> Iron & Steel Heat Room Boiler - Waste Existing 1 | F36: PJ | G36: MW | O36: =Commodities!$D$105 -> INDWST | P36: =+Commodities!$AL$8 -> DSH | R36: =+R$7 -> B | S36: =+S$28 -> Heat Room Boiler | T36: =+T15 -> Waste | U36: =+U$7 -> Existing 1
B37: =+IF(ISBLANK(D37),"*","") | D37: =M13 & P$37 & R$37 & VLOOKUP(O$37, $O$50:$P$74,2,FALSE) & "E1" -> INDSDSHBHETE1 | E37: =+M10 & " " & S$37 & " - " & T$37 & " " & U$37 -> Iron & Steel Heat Room Boiler - Dist. Heat Existing 1 | F37: PJ | G37: MW | O37: =Commodities!$D$106 -> INDHCE | P37: =+Commodities!$AL$8 -> DSH | R37: =+R$7 -> B | S37: =+S$28 -> Heat Room Boiler | T37: =+T16 -> Dist. Heat | U37: =+U$7 -> Existing 1
B38: =+IF(ISBLANK(D38),"*","") | D38: =M13 & P$38 & R$38 & VLOOKUP(O$38, $O$50:$P$74,2,FALSE) & "E2" -> INDSDSHBHETE2 | E38: =+M10 & " " & S$38 & " - " & T$38 & " " & U$38 -> Iron & Steel Heat Room Boiler - Dist. Heat Existing 2 | F38: PJ | G38: MW | O38: =Commodities!$D$108 -> INDHDE | P38: =+Commodities!$AL$8 -> DSH | R38: =+R$7 -> B | S38: =+S$28 -> Heat Room Boiler | T38: =+T17 -> Dist. Heat | U38: Existing 2
B39: =+IF(ISBLANK(D39),"*","") | D39: =M13 & P$39 & R$39 & VLOOKUP(O$39, $O$50:$P$74,2,FALSE) & "E1" -> INDSDSHBELCE1 | E39: =+M10 & " " & S$39 & " - " & T$39 & " " & U$39 -> Iron & Steel Heat Room Boiler - Electricity Existing 1 | F39: PJ | G39: MW | O39: =Commodities!$D$109 -> INDELC | P39: =+Commodities!$AL$8 -> DSH | R39: =+R$7 -> B | S39: =+S$28 -> Heat Room Boiler | T39: =+T$18 -> Electricity | U39: =+U$7 -> Existing 1
B40: =+IF(ISBLANK(D40),"*","") | D40: =M13 & P$40 & R$40 & VLOOKUP(O$40, $O$50:$P$74,2,FALSE) & "E1" -> INDSDLAAELCE1 | E40: =+M10 & " " & S$40 & " - " & T$40 & " " & U$40 -> Iron & Steel Electricity Light Appliance - Electricity Existing 1 | F40: PJ | G40: MW | O40: =Commodities!$D$109 -> INDELC | P40: =+Commodities!$AL$9 -> DLA | R40: A | S40: Electricity Light Appliance | T40: =+T$18 -> Electricity | U40: =+U$7 -> Existing 1
B41: =+IF(ISBLANK(D41),"*","") | D41: =M13 & P$41 & R$41 & VLOOKUP(O$41, $O$50:$P$74,2,FALSE) & "E1" -> INDSDEMMELCE1 | E41: =+M10 & " " & S$41 & " - " & T$41 & " " & U$41 -> Iron & Steel Electricity Motors - Electricity Existing 1 | F41: PJ | G41: MW | O41: =Commodities!$D$109 -> INDELC | P41: =+Commodities!$AL$10 -> DEM | R41: M | S41: Electricity Motors | T41: =+T$18 -> Electricity | U41: =+U$7 -> Existing 1
B42: =+IF(ISBLANK(D42),"*","") | D42: =M13 & P$42 & R$42 & VLOOKUP(O$42, $O$50:$P$74,2,FALSE) & "E1" -> INDSDTFTDSLE1 | E42: =+M10 & " " & S$42 & " - " & T$42 & " " & U$42 -> Iron & Steel Tractors, Trucks, Fishing boats, Forest machines - Diesel Existing 1 | F42: PJ | G42: MW | O42: =+Commodities!D111&","&Commodities!D112&","&Commodities!D99 -> INDDSB1,INDDSB2,INDDSL | P42: =+Commodities!$AL$11 -> DTF | R42: T | S42: Tractors, Trucks, Fishing boats, Forest machines | T42: Diesel | U42: =+U$7 -> Existing 1
B43: =+IF(ISBLANK(D43),"*","") | D43: =M13&P$43&R$43&VLOOKUP(O$43,$O$50:$P$74,2,FALSE)&"E1" -> INDSDFLTLPGE1 | E43: =+M10 & " " & S$43 & " - " & T$43 & " " & U$43 -> Iron & Steel Forklifts - LPG Existing 1 | F43: PJ | G43: MW | O43: =+Commodities!D104&","&Commodities!D113&","&Commodities!D114 -> INDLPG,INDSNG1,INDSNG2 | P43: =+Commodities!$AL$12 -> DFL | R43: =+R$42 -> T | S43: Forklifts | T43: LPG | U43: =+U$7 -> Existing 1
...

Sheet Commodities
B3: ~FI_Comm
B4: CSet | C4: Region | D4: CommName | E4: CommDesc | F4: Unit | G4: LimType | H4: CTSLvl | I4: PeakTS | J4: Ctype
B5: *Commodity Set Membership | C5: Region Name | D5: Commodity Name | E5: Commodity Description | F5: Unit | G5: Sense of the Balance EQN. | H5: Timeslice Level | I5: Peak Monitoring | J5: Electricity Indicator | T5: Index | U5: Code | V5: Code | W5: Code | X5: Sector | Y5: Text | AC5: Eurostat | AD5: Temperature Distribution | AE5: Sheet Name | AJ5: Index | AK5: Txt1 | AL5: Code | AM5: Txt2
B6: DEM | D6: =+INDEX($U$6:$U$18,M6) & INDEX($AL$6:$AL$13,L6) -> ISDPH | E6: =INDEX($X$6:$X$17,M6) & " " & INDEX($AM$6:$AM$13,L6) -> Iron & Steel Demand Process heat | F6: PJ | L6: 1 | M6: 1 | N6: =VLOOKUP(M6, $T$6:$Y$18, 6, FALSE) -> 01 Iron and steel | T6: 1 | U6: IS | V6: IIS | W6: INDS | X6: Iron & Steel | Y6: ="0"&T6&" "&AC6 -> 01 Iron and steel | AC6: Iron and steel | AD6: =AC6 -> Iron and steel | AE6: IronSteel | AJ6: 1 | AK6: Industry | AL6: DPH | AM6: Demand Process heat
D7: =+INDEX($U$6:$U$18,M7) & INDEX($AL$6:$AL$13,L7) -> ISDCO | E7: =INDEX($X$6:$X$17,M7) & " " & INDEX($AM$6:$AM$13,L7) -> Iron & Steel Demand Cooling | F7: PJ | L7: =+L6+1 -> 2 | M7: =+M6 -> 1 | T7: 2 | U7: IC | V7: ICH | W7: INDC | X7: Chemical industry | Y7: ="0"&T7&" "&AC7 -> 02 Chemical and petrochemical | AC7: Chemical and petrochemical | AD7: =AC7 -> Chemical and petrochemical | AE7: Chemical | AJ7: 2 | AK7: Industry | AL7: DCO | AM7: Demand Cooling
D8: =+INDEX($U$6:$U$18,M8) & INDEX($AL$6:$AL$13,L8) -> ISDSH | E8: =INDEX($X$6:$X$17,M8) & " " & INDEX($AM$6:$AM$13,L8) -> Iron & Steel Demand Spatial Heat | F8: PJ | L8: =+L7+1 -> 3 | M8: =+M7 -> 1 | T8: 3 | U8: IA | V8: IAL | W8: INDA | X8: Aluminium industry | Y8: ="0"&T8&" "&AC8 -> 03 Non-ferrous metal | AC8: Non-ferrous metal | AD8: =AC8 -> Non-ferrous metal | AE8: Aluminium | AJ8: 3 | AK8: Industry | AL8: DSH | AM8: Demand Spatial Heat
D9: =+INDEX($U$6:$U$18,M9) & INDEX($AL$6:$AL$13,L9) -> ISDLA | E9: =INDEX($X$6:$X$17,M9) & " " & INDEX($AM$6:$AM$13,L9) -> Iron & Steel Demand Light | F9: PJ | L9: =+L8+1 -> 4 | M9: =+M8 -> 1 | T9: 4 | U9: IG | V9: IGL | W9: INDG | X9: Glass & Concrete industry | Y9: ="0"&T9&" "&AC9 -> 04 Non-metallic minerals | AC9: Non-metallic minerals | AD9: =AC9 -> Non-metallic minerals | AE9: GlassConcrete | AJ9: 4 | AK9: Industry | AL9: DLA | AM9: Demand Light
D10: =+INDEX($U$6:$U$18,M10) & INDEX($AL$6:$AL$13,L10) -> ISDEM | E10: =INDEX($X$6:$X$17,M10) & " " & INDEX($AM$6:$AM$13,L10) -> Iron & Steel Demand Electric Motors | F10: PJ | L10: =+L9+1 -> 5 | M10: =+M9 -> 1 | T10: 5 | U10: IT | V10: ITR | W10: INDT | X10: Transport industry | Y10: ="0"&T10&" "&AC10 -> 05 Transport equipment | AC10: Transport equipment | AD10: =AC10 -> Transport equipment | AE10: Transport | AJ10: 5 | AK10: Industry | AL10: DEM | AM10: Demand Electric Motors
D11: =+INDEX($U$6:$U$18,M11) & INDEX($AL$6:$AL$13,L11) -> ISDTF | E11: =INDEX($X$6:$X$17,M11) & " " & INDEX($AM$6:$AM$13,L11) -> Iron & Steel Demand Haulage Tractors, Trucks, Fishing boats, Forest machines | F11: PJ | L11: =+L10+1 -> 6 | M11: =+M10 -> 1 | T11: 6 | U11: IM | V11: IME | W11: INDM | X11: Machinery industry | Y11: ="0"&T11&" "&AC11 -> 06 Machinery | AC11: Machinery | AD11: =AC11 -> Machinery | AE11: Machinery | AJ11: 6 | AK11: Industry | AL11: DTF | AM11: Demand Haulage Tractors, Trucks, Fishing boats, Forest machines
D12: =+INDEX($U$6:$U$18,M12) & INDEX($AL$6:$AL$13,L12) -> ISDFL | E12: =INDEX($X$6:$X$17,M12) & " " & INDEX($AM$6:$AM$13,L12) -> Iron & Steel Demand Haulage Forklifts | F12: PJ | L12: =+L11+1 -> 7 | M12: =+M11 -> 1 | T12: 7 | U12: II | V12: IMQ | W12: INDI | X12: Mining | Y12: ="0"&T12&" "&AC12 -> 07 Mining and quarrying | AC12: Mining and quarrying | AD12: =AC12 -> Mining and quarrying | AE12: Mining | AJ12: 7 | AK12: Industry | AL12: DFL | AM12: Demand Haulage Forklifts
D13: =+INDEX($U$6:$U$18,M13) & INDEX($AL$6:$AL$13,L13) -> ICDPH | E13: =INDEX($X$6:$X$17,M13) & " " & INDEX($AM$6:$AM$13,L13) -> Chemical industry Demand Process heat | F13: PJ | L13: =+L6 -> 1 | M13: =1+M8 -> 2 | N13: =VLOOKUP(M13, $T$6:$Y$18, 6, FALSE) -> 02 Chemical and petrochemical | T13: 8 | U13: IF | V13: IFD | W13: INDF | X13: Food industry | Y13: ="0"&T13&" "&AC13 -> 08 Food and tobacco | AC13: Food and tobacco | AD13: =AC13 -> Food and tobacco | AE13: Food
D14: =+INDEX($U$6:$U$18,M14) & INDEX($AL$6:$AL$13,L14) -> ICDCO | E14: =INDEX($X$6:$X$17,M14) & " " & INDEX($AM$6:$AM$13,L14) -> Chemical industry Demand Cooling | F14: PJ | L14: =+L13+1 -> 2 | M14: =+M13 -> 2 | T14: 9 | U14: IR | V14: IPP | W14: INDR | X14: Paper & Pulp industry | Y14: ="0"&T14&" "&AC14 -> 09 Paper, pulp and printing | AC14: Paper, pulp and printing | AD14: =AC14 -> Paper, pulp and printing | AE14: PulpPaper
D15: =+INDEX($U$6:$U$18,M15) & INDEX($AL$6:$AL$13,L15) -> ICDSH | E15: =INDEX($X$6:$X$17,M15) & " " & INDEX($AM$6:$AM$13,L15) -> Chemical industry Demand Spatial Heat | F15: PJ | L15: =+L14+1 -> 3 | M15: =+M14 -> 2 | T15: 10 | U15: IW | V15: IWP | W15: INDW | X15: Wood products industry | Y15: ="0"&T15&" "&AC15 -> 010 Wood and wood products | AC15: Wood and wood products | AD15: =AC15 -> Wood and wood products | AE15: Wood
D16: =+INDEX($U$6:$U$18,M16) & INDEX($AL$6:$AL$13,L16) -> ICDLA | E16: =INDEX($X$6:$X$17,M16) & " " & INDEX($AM$6:$AM$13,L16) -> Chemical industry Demand Light | F16: PJ | L16: =+L15+1 -> 4 | M16: =+M15 -> 2 | T16: 11 | U16: IL | V16: ITL | W16: INDL | X16: Textile & Leather | Y16: ="0"&T16&" "&AC16 -> 011 Textile and leather | AC16: Textile and leather | AD16: =AC16 -> Textile and leather | AE16: TextileLeather
D17: =+INDEX($U$6:$U$18,M17) & INDEX($AL$6:$AL$13,L17) -> ICDEM | E17: =INDEX($X$6:$X$17,M17) & " " & INDEX($AM$6:$AM$13,L17) -> Chemical industry Demand Electric Motors | F17: PJ | L17: =+L16+1 -> 5 | M17: =+M16 -> 2 | T17: 12 | U17: IN | V17: ICO | W17: INDN | X17: Construction | Y17: ="0"&T17&" "&AC17 -> 012 Construction | AC17: Construction | AD17: =AC17 -> Construction | AE17: Construction
D18: =+INDEX($U$6:$U$18,M18) & INDEX($AL$6:$AL$13,L18) -> ICDTF | E18: =INDEX($X$6:$X$17,M18) & " " & INDEX($AM$6:$AM$13,L18) -> Chemical industry Demand Haulage Tractors, Trucks, Fishing boats, Forest machines | F18: PJ | L18: =+L17+1 -> 6 | M18: =+M17 -> 2 | T18: 13 | U18: IO | V18: IOT | W18: INDO | X18: Other comm | Y18: ="0"&T18&" "&AC18 -> 013 Non-specified | AC18: Non-specified | AD18: =AC18 -> Non-specified | AE18: Other
D19: =+INDEX($U$6:$U$18,M19) & INDEX($AL$6:$AL$13,L19) -> ICDFL | E19: =INDEX($X$6:$X$17,M19) & " " & INDEX($AM$6:$AM$13,L19) -> Chemical industry Demand Haulage Forklifts | F19: PJ | L19: =+L18+1 -> 7 | M19: =+M18 -> 2
D20: =+INDEX($U$6:$U$18,M20) & INDEX($AL$6:$AL$13,L20) -> IADPH | E20: =INDEX($X$6:$X$17,M20) & " " & INDEX($AM$6:$AM$13,L20) -> Aluminium industry Demand Process heat | F20: PJ | L20: =+L13 -> 1 | M20: =1+M15 -> 3 | N20: =VLOOKUP(M20, $T$6:$Y$17, 6, FALSE) -> 03 Non-ferrous metal
D21: =+INDEX($U$6:$U$18,M21) & INDEX($AL$6:$AL$13,L21) -> IADCO | E21: =INDEX($X$6:$X$17,M21) & " " & INDEX($AM$6:$AM$13,L21) -> Aluminium industry Demand Cooling | F21: PJ | L21: =+L20+1 -> 2 | M21: =+M20 -> 3
D22: =+INDEX($U$6:$U$18,M22) & INDEX($AL$6:$AL$13,L22) -> IADSH | E22: =INDEX($X$6:$X$17,M22) & " " & INDEX($AM$6:$AM$13,L22) -> Aluminium industry Demand Spatial Heat | F22: PJ | L22: =+L21+1 -> 3 | M22: =+M21 -> 3
D23: =+INDEX($U$6:$U$18,M23) & INDEX($AL$6:$AL$13,L23) -> IADLA | E23: =INDEX($X$6:$X$17,M23) & " " & INDEX($AM$6:$AM$13,L23) -> Aluminium industry Demand Light | F23: PJ | L23: =+L22+1 -> 4 | M23: =+M22 -> 3
D24: =+INDEX($U$6:$U$18,M24) & INDEX($AL$6:$AL$13,L24) -> IADEM | E24: =INDEX($X$6:$X$17,M24) & " " & INDEX($AM$6:$AM$13,L24) -> Aluminium industry Demand Electric Motors | F24: PJ | L24: =+L23+1 -> 5 | M24: =+M23 -> 3
D25: =+INDEX($U$6:$U$18,M25) & INDEX($AL$6:$AL$13,L25) -> IADTF | E25: =INDEX($X$6:$X$17,M25) & " " & INDEX($AM$6:$AM$13,L25) -> Aluminium industry Demand Haulage Tractors, Trucks, Fishing boats, Forest machines | F25: PJ | L25: =+L24+1 -> 6 | M25: =+M24 -> 3
D26: =+INDEX($U$6:$U$18,M26) & INDEX($AL$6:$AL$13,L26) -> IADFL | E26: =INDEX($X$6:$X$17,M26) & " " & INDEX($AM$6:$AM$13,L26) -> Aluminium industry Demand Haulage Forklifts | F26: PJ | L26: =+L25+1 -> 7 | M26: =+M25 -> 3
D27: =+INDEX($U$6:$U$18,M27) & INDEX($AL$6:$AL$13,L27) -> IGDPH | E27: =INDEX($X$6:$X$17,M27) & " " & INDEX($AM$6:$AM$13,L27) -> Glass & Concrete industry Demand Process heat | F27: PJ | L27: =+L20 -> 1 | M27: =1+M22 -> 4 | N27: =VLOOKUP(M27, $T$6:$Y$17, 6, FALSE) -> 04 Non-metallic minerals
D28: =+INDEX($U$6:$U$18,M28) & INDEX($AL$6:$AL$13,L28) -> IGDCO | E28: =INDEX($X$6:$X$17,M28) & " " & INDEX($AM$6:$AM$13,L28) -> Glass & Concrete industry Demand Cooling | F28: PJ | L28: =+L27+1 -> 2 | M28: =+M27 -> 4
D29: =+INDEX($U$6:$U$18,M29) & INDEX($AL$6:$AL$13,L29) -> IGDSH | E29: =INDEX($X$6:$X$17,M29) & " " & INDEX($AM$6:$AM$13,L29) -> Glass & Concrete industry Demand Spatial Heat | F29: PJ | L29: =+L28+1 -> 3 | M29: =+M28 -> 4
D30: =+INDEX($U$6:$U$18,M30) & INDEX($AL$6:$AL$13,L30) -> IGDLA | E30: =INDEX($X$6:$X$17,M30) & " " & INDEX($AM$6:$AM$13,L30) -> Glass & Concrete industry Demand Light | F30: PJ | L30: =+L29+1 -> 4 | M30: =+M29 -> 4
D31: =+INDEX($U$6:$U$18,M31) & INDEX($AL$6:$AL$13,L31) -> IGDEM | E31: =INDEX($X$6:$X$17,M31) & " " & INDEX($AM$6:$AM$13,L31) -> Glass & Concrete industry Demand Electric Motors | F31: PJ | L31: =+L30+1 -> 5 | M31: =+M30 -> 4
D32: =+INDEX($U$6:$U$18,M32) & INDEX($AL$6:$AL$13,L32) -> IGDTF | E32: =INDEX($X$6:$X$17,M32) & " " & INDEX($AM$6:$AM$13,L32) -> Glass & Concrete industry Demand Haulage Tractors, Trucks, Fishing boats, Forest machines | F32: PJ | L32: =+L31+1 -> 6 | M32: =+M31 -> 4
D33: =+INDEX($U$6:$U$18,M33) & INDEX($AL$6:$AL$13,L33) -> IGDFL | E33: =INDEX($X$6:$X$17,M33) & " " & INDEX($AM$6:$AM$13,L33) -> Glass & Concrete industry Demand Haulage Forklifts | F33: PJ | L33: =+L32+1 -> 7 | M33: =+M32 -> 4
D34: =+INDEX($U$6:$U$18,M34) & INDEX($AL$6:$AL$13,L34) -> ITDPH | E34: =INDEX($X$6:$X$17,M34) & " " & INDEX($AM$6:$AM$13,L34) -> Transport industry Demand Process heat | F34: PJ | L34: =+L27 -> 1 | M34: =1+M29 -> 5 | N34: =VLOOKUP(M34, $T$6:$Y$17, 6, FALSE) -> 05 Transport equipment
D35: =+INDEX($U$6:$U$18,M35) & INDEX($AL$6:$AL$13,L35) -> ITDCO | E35: =INDEX($X$6:$X$17,M35) & " " & INDEX($AM$6:$AM$13,L35) -> Transport industry Demand Cooling | F35: PJ | L35: =+L34+1 -> 2 | M35: =+M34 -> 5
D36: =+INDEX($U$6:$U$18,M36) & INDEX($AL$6:$AL$13,L36) -> ITDSH | E36: =INDEX($X$6:$X$17,M36) & " " & INDEX($AM$6:$AM$13,L36) -> Transport industry Demand Spatial Heat | F36: PJ | L36: =+L35+1 -> 3 | M36: =+M35 -> 5
D37: =+INDEX($U$6:$U$18,M37) & INDEX($AL$6:$AL$13,L37) -> ITDLA | E37: =INDEX($X$6:$X$17,M37) & " " & INDEX($AM$6:$AM$13,L37) -> Transport industry Demand Light | F37: PJ | L37: =+L36+1 -> 4 | M37: =+M36 -> 5
D38: =+INDEX($U$6:$U$18,M38) & INDEX($AL$6:$AL$13,L38) -> ITDEM | E38: =INDEX($X$6:$X$17,M38) & " " & INDEX($AM$6:$AM$13,L38) -> Transport industry Demand Electric Motors | F38: PJ | L38: =+L37+1 -> 5 | M38: =+M37 -> 5
D39: =+INDEX($U$6:$U$18,M39) & INDEX($AL$6:$AL$13,L39) -> ITDTF | E39: =INDEX($X$6:$X$17,M39) & " " & INDEX($AM$6:$AM$13,L39) -> Transport industry Demand Haulage Tractors, Trucks, Fishing boats, Forest machines | F39: PJ | L39: =+L38+1 -> 6 | M39: =+M38 -> 5
D40: =+INDEX($U$6:$U$18,M40) & INDEX($AL$6:$AL$13,L40) -> ITDFL | E40: =INDEX($X$6:$X$17,M40) & " " & INDEX($AM$6:$AM$13,L40) -> Transport industry Demand Haulage Forklifts | F40: PJ | L40: =+L39+1 -> 7 | M40: =+M39 -> 5
D41: =+INDEX($U$6:$U$18,M41) & INDEX($AL$6:$AL$13,L41) -> IMDPH | E41: =INDEX($X$6:$X$17,M41) & " " & INDEX($AM$6:$AM$13,L41) -> Machinery industry Demand Process heat | F41: PJ | L41: =+L34 -> 1 | M41: =1+M36 -> 6 | N41: =VLOOKUP(M41, $T$6:$Y$17, 6, FALSE) -> 06 Machinery
D42: =+INDEX($U$6:$U$18,M42) & INDEX($AL$6:$AL$13,L42) -> IMDCO | E42: =INDEX($X$6:$X$17,M42) & " " & INDEX($AM$6:$AM$13,L42) -> Machinery industry Demand Cooling | F42: PJ | L42: =+L41+1 -> 2 | M42: =+M41 -> 6
...

Sheet Demand
B2: =IronSteel!V76 -> 2010 | C2: Demand | I2: Information for function INDIRECT():
B3: DEMAND | D3: Block size: | E3: 7
I4: This colour: Input
B5: ~FI_T
B6: CommName | C6: *Description | D6: *Unit | E6: DEMAND~AZ1 | F6: DEMAND~AZ2 | G6: DEMAND~AZ3 | I6: Sheet | J6: AZ1 Col | K6: AZ2 Col | L6: AZ3 Col | M6: Row 1 | N6: Row 2 | P6: Check
B7: =+Commodities!D6 -> ISDPH | C7: =+Commodities!E6 -> Iron & Steel Demand Process heat | D7: =+Commodities!F6 -> PJ | E7: =+SUM(INDIRECT("'" & $I7 & "'!" & J7 & $M7 & IF(ISBLANK($N7),"",":" & J7 & $N7))) -> 236.92288 | F7: =+SUM(INDIRECT("'" & $I7 & "'!" & K7 & $M7 & IF(ISBLANK($N7),"",":" & K7 & $N7))) -> 0 | G7: =+SUM(INDIRECT("'" & $I7 & "'!" & L7 & $M7 & IF(ISBLANK($N7),"",":" & L7 & $N7))) -> 0 | I7: =Commodities!AE6 -> IronSteel | J7: =SUBSTITUTE(ADDRESS(1,COLUMN(IronSteel!AQ1),4),"1","") -> AQ | K7: =SUBSTITUTE(ADDRESS(1,COLUMN(IronSteel!AR1),4),"1","") -> AR | L7: =SUBSTITUTE(ADDRESS(1,COLUMN(IronSteel!AS1),4),"1","") -> AS | M7: 26 | N7: 37 | P7: =+SUM(INDIRECT("'" & I7 & "'!" & "AQ26:AR62")) - SUM(E7:F13) -> 0
B8: =+Commodities!D7 -> ISDCO | C8: =+Commodities!E7 -> Iron & Steel Demand Cooling | D8: =+Commodities!F7 -> PJ | E8: =+SUM(INDIRECT("'" & $I8 & "'!" & J8 & $M8 & IF(ISBLANK($N8),"",":" & J8 & $N8))) -> 8.8988858 | F8: =+SUM(INDIRECT("'" & $I8 & "'!" & K8 & $M8 & IF(ISBLANK($N8),"",":" & K8 & $N8))) -> 0 | G8: =+SUM(INDIRECT("'" & $I8 & "'!" & L8 & $M8 & IF(ISBLANK($N8),"",":" & L8 & $N8))) -> 0 | I8: =+I7 -> IronSteel | J8: =+J7 -> AQ | K8: =+K7 -> AR | L8: =+L7 -> AS | M8: 38 | N8: 46
B9: =+Commodities!D8 -> ISDSH | C9: =+Commodities!E8 -> Iron & Steel Demand Spatial Heat | D9: =+Commodities!F8 -> PJ | E9: =+SUM(INDIRECT("'" & $I9 & "'!" & J9 & $M9 & IF(ISBLANK($N9),"",":" & J9 & $N9))) -> 4.4828062 | F9: =+SUM(INDIRECT("'" & $I9 & "'!" & K9 & $M9 & IF(ISBLANK($N9),"",":" & K9 & $N9))) -> 0 | G9: =+SUM(INDIRECT("'" & $I9 & "'!" & L9 & $M9 & IF(ISBLANK($N9),"",":" & L9 & $N9))) -> 0 | I9: =+I8 -> IronSteel | J9: =+J8 -> AQ | K9: =+K8 -> AR | L9: =+L8 -> AS | M9: 47 | N9: 58
B10: =+Commodities!D9 -> ISDLA | C10: =+Commodities!E9 -> Iron & Steel Demand Light | D10: =+Commodities!F9 -> PJ | E10: =+SUM(INDIRECT("'" & $I10 & "'!" & J10 & $M10 & IF(ISBLANK($N10),"",":" & J10 & $N10))) -> 21.457665 | F10: =+SUM(INDIRECT("'" & $I10 & "'!" & K10 & $M10 & IF(ISBLANK($N10),"",":" & K10 & $N10))) -> 0 | G10: =+SUM(INDIRECT("'" & $I10 & "'!" & L10 & $M10 & IF(ISBLANK($N10),"",":" & L10 & $N10))) -> 0 | I10: =+I9 -> IronSteel | J10: =+J9 -> AQ | K10: =+K9 -> AR | L10: =+L9 -> AS | M10: 59
B11: =+Commodities!D10 -> ISDEM | C11: =+Commodities!E10 -> Iron & Steel Demand Electric Motors | D11: =+Commodities!F10 -> PJ | E11: =+SUM(INDIRECT("'" & $I11 & "'!" & J11 & $M11 & IF(ISBLANK($N11),"",":" & J11 & $N11))) -> 47.792068 | F11: =+SUM(INDIRECT("'" & $I11 & "'!" & K11 & $M11 & IF(ISBLANK($N11),"",":" & K11 & $N11))) -> 0 | G11: =+SUM(INDIRECT("'" & $I11 & "'!" & L11 & $M11 & IF(ISBLANK($N11),"",":" & L11 & $N11))) -> 0 | I11: =+I10 -> IronSteel | J11: =+J10 -> AQ | K11: =+K10 -> AR | L11: =+L10 -> AS | M11: 60
B12: =+Commodities!D11 -> ISDTF | C12: =+Commodities!E11 -> Iron & Steel Demand Haulage Tractors, Trucks, Fishing boats, Forest machines | D12: =+Commodities!F11 -> PJ | E12: =+SUM(INDIRECT("'" & $I12 & "'!" & J12 & $M12 & IF(ISBLANK($N12),"",":" & J12 & $N12))) -> 0.96514022 | F12: =+SUM(INDIRECT("'" & $I12 & "'!" & K12 & $M12 & IF(ISBLANK($N12),"",":" & K12 & $N12))) -> 0 | G12: =+SUM(INDIRECT("'" & $I12 & "'!" & L12 & $M12 & IF(ISBLANK($N12),"",":" & L12 & $N12))) -> 0 | I12: =+I11 -> IronSteel | J12: =+J11 -> AQ | K12: =+K11 -> AR | L12: =+L11 -> AS | M12: 61
B13: =+Commodities!D12 -> ISDFL | C13: =+Commodities!E12 -> Iron & Steel Demand Haulage Forklifts | D13: =+Commodities!F12 -> PJ | E13: =+SUM(INDIRECT("'" & $I13 & "'!" & J13 & $M13 & IF(ISBLANK($N13),"",":" & J13 & $N13))) -> 0.91112576 | F13: =+SUM(INDIRECT("'" & $I13 & "'!" & K13 & $M13 & IF(ISBLANK($N13),"",":" & K13 & $N13))) -> 0 | G13: =+SUM(INDIRECT("'" & $I13 & "'!" & L13 & $M13 & IF(ISBLANK($N13),"",":" & L13 & $N13))) -> 0 | I13: =+I12 -> IronSteel | J13: =+J12 -> AQ | K13: =+K12 -> AR | L13: =+L12 -> AS | M13: 62
B14: =+Commodities!D13 -> ICDPH | C14: =+Commodities!E13 -> Chemical industry Demand Process heat | D14: =+Commodities!F13 -> PJ | E14: =+SUM(INDIRECT("'" & $I14 & "'!" & J14 & $M14 & IF(ISBLANK($N14),"",":" & J14 & $N14))) -> 288.04192 | F14: =+SUM(INDIRECT("'" & $I14 & "'!" & K14 & $M14 & IF(ISBLANK($N14),"",":" & K14 & $N14))) -> 0 | G14: =+SUM(INDIRECT("'" & $I14 & "'!" & L14 & $M14 & IF(ISBLANK($N14),"",":" & L14 & $N14))) -> 0 | I14: =Commodities!AE7 -> Chemical | J14: =+J7 -> AQ | K14: =+K7 -> AR | L14: =+L7 -> AS | M14: =+M7 -> 26 | N14: =+N7 -> 37 | P14: =+SUM(INDIRECT("'" & I14 & "'!" & "AQ26:AR62")) - SUM(E14:F20) -> 0
B15: =+Commodities!D14 -> ICDCO | C15: =+Commodities!E14 -> Chemical industry Demand Cooling | D15: =+Commodities!F14 -> PJ | E15: =+SUM(INDIRECT("'" & $I15 & "'!" & J15 & $M15 & IF(ISBLANK($N15),"",":" & J15 & $N15))) -> 18.909496 | F15: =+SUM(INDIRECT("'" & $I15 & "'!" & K15 & $M15 & IF(ISBLANK($N15),"",":" & K15 & $N15))) -> 0 | G15: =+SUM(INDIRECT("'" & $I15 & "'!" & L15 & $M15 & IF(ISBLANK($N15),"",":" & L15 & $N15))) -> 0 | I15: =+I14 -> Chemical | J15: =+J8 -> AQ | K15: =+K8 -> AR | L15: =+L8 -> AS | M15: =+M8 -> 38 | N15: =+N8 -> 46
B16: =+Commodities!D15 -> ICDSH | C16: =+Commodities!E15 -> Chemical industry Demand Spatial Heat | D16: =+Commodities!F15 -> PJ | E16: =+SUM(INDIRECT("'" & $I16 & "'!" & J16 & $M16 & IF(ISBLANK($N16),"",":" & J16 & $N16))) -> 97.974438 | F16: =+SUM(INDIRECT("'" & $I16 & "'!" & K16 & $M16 & IF(ISBLANK($N16),"",":" & K16 & $N16))) -> 0 | G16: =+SUM(INDIRECT("'" & $I16 & "'!" & L16 & $M16 & IF(ISBLANK($N16),"",":" & L16 & $N16))) -> 0 | I16: =+I15 -> Chemical | J16: =+J9 -> AQ | K16: =+K9 -> AR | L16: =+L9 -> AS | M16: =+M9 -> 47 | N16: =+N9 -> 58
B17: =+Commodities!D16 -> ICDLA | C17: =+Commodities!E16 -> Chemical industry Demand Light | D17: =+Commodities!F16 -> PJ | E17: =+SUM(INDIRECT("'" & $I17 & "'!" & J17 & $M17 & IF(ISBLANK($N17),"",":" & J17 & $N17))) -> 13.188926 | F17: =+SUM(INDIRECT("'" & $I17 & "'!" & K17 & $M17 & IF(ISBLANK($N17),"",":" & K17 & $N17))) -> 0 | G17: =+SUM(INDIRECT("'" & $I17 & "'!" & L17 & $M17 & IF(ISBLANK($N17),"",":" & L17 & $N17))) -> 0 | I17: =+I16 -> Chemical | J17: =+J10 -> AQ | K17: =+K10 -> AR | L17: =+L10 -> AS | M17: =+M10 -> 59
B18: =+Commodities!D17 -> ICDEM | C18: =+Commodities!E17 -> Chemical industry Demand Electric Motors | D18: =+Commodities!F17 -> PJ | E18: =+SUM(INDIRECT("'" & $I18 & "'!" & J18 & $M18 & IF(ISBLANK($N18),"",":" & J18 & $N18))) -> 152.6147 | F18: =+SUM(INDIRECT("'" & $I18 & "'!" & K18 & $M18 & IF(ISBLANK($N18),"",":" & K18 & $N18))) -> 0 | G18: =+SUM(INDIRECT("'" & $I18 & "'!" & L18 & $M18 & IF(ISBLANK($N18),"",":" & L18 & $N18))) -> 0 | I18: =+I17 -> Chemical | J18: =+J11 -> AQ | K18: =+K11 -> AR | L18: =+L11 -> AS | M18: =+M11 -> 60
B19: =+Commodities!D18 -> ICDTF | C19: =+Commodities!E18 -> Chemical industry Demand Haulage Tractors, Trucks, Fishing boats, Forest machines | D19: =+Commodities!F18 -> PJ | E19: =+SUM(INDIRECT("'" & $I19 & "'!" & J19 & $M19 & IF(ISBLANK($N19),"",":" & J19 & $N19))) -> 2.9168698 | F19: =+SUM(INDIRECT("'" & $I19 & "'!" & K19 & $M19 & IF(ISBLANK($N19),"",":" & K19 & $N19))) -> 0 | G19: =+SUM(INDIRECT("'" & $I19 & "'!" & L19 & $M19 & IF(ISBLANK($N19),"",":" & L19 & $N19))) -> 0 | I19: =+I18 -> Chemical | J19: =+J12 -> AQ | K19: =+K12 -> AR | L19: =+L12 -> AS | M19: =+M12 -> 61
B20: =+Commodities!D19 -> ICDFL | C20: =+Commodities!E19 -> Chemical industry Demand Haulage Forklifts | D20: =+Commodities!F19 -> PJ | E20: =+SUM(INDIRECT("'" & $I20 & "'!" & J20 & $M20 & IF(ISBLANK($N20),"",":" & J20 & $N20))) -> 0 | F20: =+SUM(INDIRECT("'" & $I20 & "'!" & K20 & $M20 & IF(ISBLANK($N20),"",":" & K20 & $N20))) -> 0 | G20: =+SUM(INDIRECT("'" & $I20 & "'!" & L20 & $M20 & IF(ISBLANK($N20),"",":" & L20 & $N20))) -> 0 | I20: =+I19 -> Chemical | J20: =+J13 -> AQ | K20: =+K13 -> AR | L20: =+L13 -> AS | M20: =+M13 -> 62
B21: =+Commodities!D20 -> IADPH | C21: =+Commodities!E20 -> Aluminium industry Demand Process heat | D21: =+Commodities!F20 -> PJ | E21: =+SUM(INDIRECT("'" & $I21 & "'!" & J21 & $M21 & IF(ISBLANK($N21),"",":" & J21 & $N21))) -> 61.166781 | F21: =+SUM(INDIRECT("'" & $I21 & "'!" & K21 & $M21 & IF(ISBLANK($N21),"",":" & K21 & $N21))) -> 0 | G21: =+SUM(INDIRECT("'" & $I21 & "'!" & L21 & $M21 & IF(ISBLANK($N21),"",":" & L21 & $N21))) -> 0 | I21: =Commodities!AE8 -> Aluminium | J21: =+J14 -> AQ | K21: =+K14 -> AR | L21: =+L14 -> AS | M21: =+M14 -> 26 | N21: =+N14 -> 37 | P21: =+SUM(INDIRECT("'" & I21 & "'!" & "AQ26:AR62")) - SUM(E21:F27) -> 0
B22: =+Commodities!D21 -> IADCO | C22: =+Commodities!E21 -> Aluminium industry Demand Cooling | D22: =+Commodities!F21 -> PJ | E22: =+SUM(INDIRECT("'" & $I22 & "'!" & J22 & $M22 & IF(ISBLANK($N22),"",":" & J22 & $N22))) -> 0 | F22: =+SUM(INDIRECT("'" & $I22 & "'!" & K22 & $M22 & IF(ISBLANK($N22),"",":" & K22 & $N22))) -> 0 | G22: =+SUM(INDIRECT("'" & $I22 & "'!" & L22 & $M22 & IF(ISBLANK($N22),"",":" & L22 & $N22))) -> 0 | I22: =+I21 -> Aluminium | J22: =+J15 -> AQ | K22: =+K15 -> AR | L22: =+L15 -> AS | M22: =+M15 -> 38 | N22: =+N15 -> 46
B23: =+Commodities!D22 -> IADSH | C23: =+Commodities!E22 -> Aluminium industry Demand Spatial Heat | D23: =+Commodities!F22 -> PJ | E23: =+SUM(INDIRECT("'" & $I23 & "'!" & J23 & $M23 & IF(ISBLANK($N23),"",":" & J23 & $N23))) -> 3.1681708 | F23: =+SUM(INDIRECT("'" & $I23 & "'!" & K23 & $M23 & IF(ISBLANK($N23),"",":" & K23 & $N23))) -> 0 | G23: =+SUM(INDIRECT("'" & $I23 & "'!" & L23 & $M23 & IF(ISBLANK($N23),"",":" & L23 & $N23))) -> 0 | I23: =+I22 -> Aluminium | J23: =+J16 -> AQ | K23: =+K16 -> AR | L23: =+L16 -> AS | M23: =+M16 -> 47 | N23: =+N16 -> 58
B24: =+Commodities!D23 -> IADLA | C24: =+Commodities!E23 -> Aluminium industry Demand Light | D24: =+Commodities!F23 -> PJ | E24: =+SUM(INDIRECT("'" & $I24 & "'!" & J24 & $M24 & IF(ISBLANK($N24),"",":" & J24 & $N24))) -> 3.1929334 | F24: =+SUM(INDIRECT("'" & $I24 & "'!" & K24 & $M24 & IF(ISBLANK($N24),"",":" & K24 & $N24))) -> 0 | G24: =+SUM(INDIRECT("'" & $I24 & "'!" & L24 & $M24 & IF(ISBLANK($N24),"",":" & L24 & $N24))) -> 0 | I24: =+I23 -> Aluminium | J24: =+J17 -> AQ | K24: =+K17 -> AR | L24: =+L17 -> AS | M24: =+M17 -> 59
B25: =+Commodities!D24 -> IADEM | C25: =+Commodities!E24 -> Aluminium industry Demand Electric Motors | D25: =+Commodities!F24 -> PJ | E25: =+SUM(INDIRECT("'" & $I25 & "'!" & J25 & $M25 & IF(ISBLANK($N25),"",":" & J25 & $N25))) -> 15.719042 | F25: =+SUM(INDIRECT("'" & $I25 & "'!" & K25 & $M25 & IF(ISBLANK($N25),"",":" & K25 & $N25))) -> 0 | G25: =+SUM(INDIRECT("'" & $I25 & "'!" & L25 & $M25 & IF(ISBLANK($N25),"",":" & L25 & $N25))) -> 0 | I25: =+I24 -> Aluminium | J25: =+J18 -> AQ | K25: =+K18 -> AR | L25: =+L18 -> AS | M25: =+M18 -> 60
B26: =+Commodities!D25 -> IADTF | C26: =+Commodities!E25 -> Aluminium industry Demand Haulage Tractors, Trucks, Fishing boats, Forest machines | D26: =+Commodities!F25 -> PJ | E26: =+SUM(INDIRECT("'" & $I26 & "'!" & J26 & $M26 & IF(ISBLANK($N26),"",":" & J26 & $N26))) -> 1.3726509 | F26: =+SUM(INDIRECT("'" & $I26 & "'!" & K26 & $M26 & IF(ISBLANK($N26),"",":" & K26 & $N26))) -> 0 | G26: =+SUM(INDIRECT("'" & $I26 & "'!" & L26 & $M26 & IF(ISBLANK($N26),"",":" & L26 & $N26))) -> 0 | I26: =+I25 -> Aluminium | J26: =+J19 -> AQ | K26: =+K19 -> AR | L26: =+L19 -> AS | M26: =+M19 -> 61
B27: =+Commodities!D26 -> IADFL | C27: =+Commodities!E26 -> Aluminium industry Demand Haulage Forklifts | D27: =+Commodities!F26 -> PJ | E27: =+SUM(INDIRECT("'" & $I27 & "'!" & J27 & $M27 & IF(ISBLANK($N27),"",":" & J27 & $N27))) -> 0.18412802 | F27: =+SUM(INDIRECT("'" & $I27 & "'!" & K27 & $M27 & IF(ISBLANK($N27),"",":" & K27 & $N27))) -> 0 | G27: =+SUM(INDIRECT("'" & $I27 & "'!" & L27 & $M27 & IF(ISBLANK($N27),"",":" & L27 & $N27))) -> 0 | I27: =+I26 -> Aluminium | J27: =+J20 -> AQ | K27: =+K20 -> AR | L27: =+L20 -> AS | M27: =+M20 -> 62
B28: =+Commodities!D27 -> IGDPH | C28: =+Commodities!E27 -> Glass & Concrete industry Demand Process heat | D28: =+Commodities!F27 -> PJ | E28: =+SUM(INDIRECT("'" & $I28 & "'!" & J28 & $M28 & IF(ISBLANK($N28),"",":" & J28 & $N28))) -> 198.09458 | F28: =+SUM(INDIRECT("'" & $I28 & "'!" & K28 & $M28 & IF(ISBLANK($N28),"",":" & K28 & $N28))) -> 0 | G28: =+SUM(INDIRECT("'" & $I28 & "'!" & L28 & $M28 & IF(ISBLANK($N28),"",":" & L28 & $N28))) -> 0 | I28: =Commodities!AE9 -> GlassConcrete | J28: =+J21 -> AQ | K28: =+K21 -> AR | L28: =+L21 -> AS | M28: =+M21 -> 26 | N28: =+N21 -> 37 | P28: =+SUM(INDIRECT("'" & I28 & "'!" & "AQ26:AR62")) - SUM(E28:F34) -> 0
B29: =+Commodities!D28 -> IGDCO | C29: =+Commodities!E28 -> Glass & Concrete industry Demand Cooling | D29: =+Commodities!F28 -> PJ | E29: =+SUM(INDIRECT("'" & $I29 & "'!" & J29 & $M29 & IF(ISBLANK($N29),"",":" & J29 & $N29))) -> 0 | F29: =+SUM(INDIRECT("'" & $I29 & "'!" & K29 & $M29 & IF(ISBLANK($N29),"",":" & K29 & $N29))) -> 0 | G29: =+SUM(INDIRECT("'" & $I29 & "'!" & L29 & $M29 & IF(ISBLANK($N29),"",":" & L29 & $N29))) -> 0 | I29: =+I28 -> GlassConcrete | J29: =+J22 -> AQ | K29: =+K22 -> AR | L29: =+L22 -> AS | M29: =+M22 -> 38 | N29: =+N22 -> 46
B30: =+Commodities!D29 -> IGDSH | C30: =+Commodities!E29 -> Glass & Concrete industry Demand Spatial Heat | D30: =+Commodities!F29 -> PJ | E30: =+SUM(INDIRECT("'" & $I30 & "'!" & J30 & $M30 & IF(ISBLANK($N30),"",":" & J30 & $N30))) -> 0.72469791 | F30: =+SUM(INDIRECT("'" & $I30 & "'!" & K30 & $M30 & IF(ISBLANK($N30),"",":" & K30 & $N30))) -> 0 | G30: =+SUM(INDIRECT("'" & $I30 & "'!" & L30 & $M30 & IF(ISBLANK($N30),"",":" & L30 & $N30))) -> 0 | I30: =+I29 -> GlassConcrete | J30: =+J23 -> AQ | K30: =+K23 -> AR | L30: =+L23 -> AS | M30: =+M23 -> 47 | N30: =+N23 -> 58
B31: =+Commodities!D30 -> IGDLA | C31: =+Commodities!E30 -> Glass & Concrete industry Demand Light | D31: =+Commodities!F30 -> PJ | E31: =+SUM(INDIRECT("'" & $I31 & "'!" & J31 & $M31 & IF(ISBLANK($N31),"",":" & J31 & $N31))) -> 4.4042497 | F31: =+SUM(INDIRECT("'" & $I31 & "'!" & K31 & $M31 & IF(ISBLANK($N31),"",":" & K31 & $N31))) -> 0 | G31: =+SUM(INDIRECT("'" & $I31 & "'!" & L31 & $M31 & IF(ISBLANK($N31),"",":" & L31 & $N31))) -> 0 | I31: =+I30 -> GlassConcrete | J31: =+J24 -> AQ | K31: =+K24 -> AR | L31: =+L24 -> AS | M31: =+M24 -> 59
B32: =+Commodities!D31 -> IGDEM | C32: =+Commodities!E31 -> Glass & Concrete industry Demand Electric Motors | D32: =+Commodities!F31 -> PJ | E32: =+SUM(INDIRECT("'" & $I32 & "'!" & J32 & $M32 & IF(ISBLANK($N32),"",":" & J32 & $N32))) -> 39.638169 | F32: =+SUM(INDIRECT("'" & $I32 & "'!" & K32 & $M32 & IF(ISBLANK($N32),"",":" & K32 & $N32))) -> 0 | G32: =+SUM(INDIRECT("'" & $I32 & "'!" & L32 & $M32 & IF(ISBLANK($N32),"",":" & L32 & $N32))) -> 0 | I32: =+I31 -> GlassConcrete | J32: =+J25 -> AQ | K32: =+K25 -> AR | L32: =+L25 -> AS | M32: =+M25 -> 60
B33: =+Commodities!D32 -> IGDTF | C33: =+Commodities!E32 -> Glass & Concrete industry Demand Haulage Tractors, Trucks, Fishing boats, Forest machines | D33: =+Commodities!F32 -> PJ | E33: =+SUM(INDIRECT("'" & $I33 & "'!" & J33 & $M33 & IF(ISBLANK($N33),"",":" & J33 & $N33))) -> 12.396657 | F33: =+SUM(INDIRECT("'" & $I33 & "'!" & K33 & $M33 & IF(ISBLANK($N33),"",":" & K33 & $N33))) -> 0 | G33: =+SUM(INDIRECT("'" & $I33 & "'!" & L33 & $M33 & IF(ISBLANK($N33),"",":" & L33 & $N33))) -> 0 | I33: =+I32 -> GlassConcrete | J33: =+J26 -> AQ | K33: =+K26 -> AR | L33: =+L26 -> AS | M33: =+M26 -> 61
B34: =+Commodities!D33 -> IGDFL | C34: =+Commodities!E33 -> Glass & Concrete industry Demand Haulage Forklifts | D34: =+Commodities!F33 -> PJ | E34: =+SUM(INDIRECT("'" & $I34 & "'!" & J34 & $M34 & IF(ISBLANK($N34),"",":" & J34 & $N34))) -> 0.62142617 | F34: =+SUM(INDIRECT("'" & $I34 & "'!" & K34 & $M34 & IF(ISBLANK($N34),"",":" & K34 & $N34))) -> 0 | G34: =+SUM(INDIRECT("'" & $I34 & "'!" & L34 & $M34 & IF(ISBLANK($N34),"",":" & L34 & $N34))) -> 0 | I34: =+I33 -> GlassConcrete | J34: =+J27 -> AQ | K34: =+K27 -> AR | L34: =+L27 -> AS | M34: =+M27 -> 62
B35: =+Commodities!D34 -> ITDPH | C35: =+Commodities!E34 -> Transport industry Demand Process heat | D35: =+Commodities!F34 -> PJ | E35: =+SUM(INDIRECT("'" & $I35 & "'!" & J35 & $M35 & IF(ISBLANK($N35),"",":" & J35 & $N35))) -> 40.250648 | F35: =+SUM(INDIRECT("'" & $I35 & "'!" & K35 & $M35 & IF(ISBLANK($N35),"",":" & K35 & $N35))) -> 0 | G35: =+SUM(INDIRECT("'" & $I35 & "'!" & L35 & $M35 & IF(ISBLANK($N35),"",":" & L35 & $N35))) -> 0 | I35: =Commodities!AE10 -> Transport | J35: =+J28 -> AQ | K35: =+K28 -> AR | L35: =+L28 -> AS | M35: =+M28 -> 26 | N35: =+N28 -> 37 | P35: =+SUM(INDIRECT("'" & I35 & "'!" & "AQ26:AR62")) - SUM(E35:F41) -> 0
B36: =+Commodities!D35 -> ITDCO | C36: =+Commodities!E35 -> Transport industry Demand Cooling | D36: =+Commodities!F35 -> PJ | E36: =+SUM(INDIRECT("'" & $I36 & "'!" & J36 & $M36 & IF(ISBLANK($N36),"",":" & J36 & $N36))) -> 5.859017 | F36: =+SUM(INDIRECT("'" & $I36 & "'!" & K36 & $M36 & IF(ISBLANK($N36),"",":" & K36 & $N36))) -> 0 | G36: =+SUM(INDIRECT("'" & $I36 & "'!" & L36 & $M36 & IF(ISBLANK($N36),"",":" & L36 & $N36))) -> 0 | I36: =+I35 -> Transport | J36: =+J29 -> AQ | K36: =+K29 -> AR | L36: =+L29 -> AS | M36: =+M29 -> 38 | N36: =+N29 -> 46
B37: =+Commodities!D36 -> ITDSH | C37: =+Commodities!E36 -> Transport industry Demand Spatial Heat | D37: =+Commodities!F36 -> PJ | E37: =+SUM(INDIRECT("'" & $I37 & "'!" & J37 & $M37 & IF(ISBLANK($N37),"",":" & J37 & $N37))) -> 4.6815523 | F37: =+SUM(INDIRECT("'" & $I37 & "'!" & K37 & $M37 & IF(ISBLANK($N37),"",":" & K37 & $N37))) -> 0 | G37: =+SUM(INDIRECT("'" & $I37 & "'!" & L37 & $M37 & IF(ISBLANK($N37),"",":" & L37 & $N37))) -> 0 | I37: =+I36 -> Transport | J37: =+J30 -> AQ | K37: =+K30 -> AR | L37: =+L30 -> AS | M37: =+M30 -> 47 | N37: =+N30 -> 58
B38: =+Commodities!D37 -> ITDLA | C38: =+Commodities!E37 -> Transport industry Demand Light | D38: =+Commodities!F37 -> PJ | E38: =+SUM(INDIRECT("'" & $I38 & "'!" & J38 & $M38 & IF(ISBLANK($N38),"",":" & J38 & $N38))) -> 6.4216873 | F38: =+SUM(INDIRECT("'" & $I38 & "'!" & K38 & $M38 & IF(ISBLANK($N38),"",":" & K38 & $N38))) -> 0 | G38: =+SUM(INDIRECT("'" & $I38 & "'!" & L38 & $M38 & IF(ISBLANK($N38),"",":" & L38 & $N38))) -> 0 | I38: =+I37 -> Transport | J38: =+J31 -> AQ | K38: =+K31 -> AR | L38: =+L31 -> AS | M38: =+M31 -> 59
B39: =+Commodities!D38 -> ITDEM | C39: =+Commodities!E38 -> Transport industry Demand Electric Motors | D39: =+Commodities!F38 -> PJ | E39: =+SUM(INDIRECT("'" & $I39 & "'!" & J39 & $M39 & IF(ISBLANK($N39),"",":" & J39 & $N39))) -> 31.466233 | F39: =+SUM(INDIRECT("'" & $I39 & "'!" & K39 & $M39 & IF(ISBLANK($N39),"",":" & K39 & $N39))) -> 0 | G39: =+SUM(INDIRECT("'" & $I39 & "'!" & L39 & $M39 & IF(ISBLANK($N39),"",":" & L39 & $N39))) -> 0 | I39: =+I38 -> Transport | J39: =+J32 -> AQ | K39: =+K32 -> AR | L39: =+L32 -> AS | M39: =+M32 -> 60
B40: =+Commodities!D39 -> ITDTF | C40: =+Commodities!E39 -> Transport industry Demand Haulage Tractors, Trucks, Fishing boats, Forest machines | D40: =+Commodities!F39 -> PJ | E40: =+SUM(INDIRECT("'" & $I40 & "'!" & J40 & $M40 & IF(ISBLANK($N40),"",":" & J40 & $N40))) -> 3.7747741 | F40: =+SUM(INDIRECT("'" & $I40 & "'!" & K40 & $M40 & IF(ISBLANK($N40),"",":" & K40 & $N40))) -> 0 | G40: =+SUM(INDIRECT("'" & $I40 & "'!" & L40 & $M40 & IF(ISBLANK($N40),"",":" & L40 & $N40))) -> 0 | I40: =+I39 -> Transport | J40: =+J33 -> AQ | K40: =+K33 -> AR | L40: =+L33 -> AS | M40: =+M33 -> 61
B41: =+Commodities!D40 -> ITDFL | C41: =+Commodities!E40 -> Transport industry Demand Haulage Forklifts | D41: =+Commodities!F40 -> PJ | E41: =+SUM(INDIRECT("'" & $I41 & "'!" & J41 & $M41 & IF(ISBLANK($N41),"",":" & J41 & $N41))) -> 0.17262888 | F41: =+SUM(INDIRECT("'" & $I41 & "'!" & K41 & $M41 & IF(ISBLANK($N41),"",":" & K41 & $N41))) -> 0 | G41: =+SUM(INDIRECT("'" & $I41 & "'!" & L41 & $M41 & IF(ISBLANK($N41),"",":" & L41 & $N41))) -> 0 | I41: =+I40 -> Transport | J41: =+J34 -> AQ | K41: =+K34 -> AR | L41: =+L34 -> AS | M41: =+M34 -> 62
...

Sheet IronSteel
C2: Index: 1 - 9 | D2: 1 | E2: In sheets 'Commodities', 'Processes', 'Pivot Agg 1' and 'Energy matrix'
C4: Sheet: | D4: Commodities
C5: Sector: | D5: =+INDEX(Commodities!$X$6:$X$18,D2) -> Iron & Steel
D6: =+INDEX(Commodities!$Y$6:$Y$18,D2) -> 01 Iron and steel | F6: =+"Give 'Index' in cell " & SUBSTITUTE(CELL("address",D2),"$","") & "." -> Give 'Index' in cell D2.
F7: Values: 1 to 10.
C8: Sheet: | D8: Processes
C9: Sector: | D9: =+OFFSET(Processes!$M$11,D11,0) -> 01 Iron and steel
C10: Block size: | D10: =+ROW(Processes!$M$44) - ROW(Processes!$M$7) -> 37
C11: Block offset: | D11: =+$D$10*$D$2-$D$10 -> 0
C13: Sheet: | D13: Energy matrix
C14: Sector: | D14: =+INDEX('Energy matrix'!$C$4:$N$4,1,D2) -> Iron and steel
G19: Relaxation factor for calibration | AK19: 2010 | AX19: 2015 | BK19: 2019
G20: 2010 | J20: 2015 | M20: 2019
G21: 1.001 | H21: 1.001 | I21: 1.001 | J21: 1.01 | K21: 1.01 | L21: 1.01 | M21: 1.01 | N21: 1.01 | O21: 1.01 | AN21: Energy service demand | BA21: Energy service demand | BN21: Energy service demand
AN22: AZ1 | AO22: AZ2 | AP22: AZ3 | BA22: AZ1 | BB22: AZ2 | BC22: AZ3 | BN22: AZ1 | BO22: AZ2 | BP22: AZ3
F23: ~FI_T | AN23: {=INDEX(RegSplit!$B$4:$AN$6,MATCH(AN22,RegSplit!$A$4:$A$6,0),MATCH($D$6&AK19,RegSplit!$B$2:$AN$2&RegSplit!$B$3:$AN$3,0))} -> 1 | AO23: {=INDEX(RegSplit!$B$4:$AN$6,MATCH(AO22,RegSplit!$A$4:$A$6,0),MATCH($D$6&AK19,RegSplit!$B$2:$AN$2&RegSplit!$B$3:$AN$3,0))} -> 0 | AP23: {=INDEX(RegSplit!$B$4:$AN$6,MATCH(AP22,RegSplit!$A$4:$A$6,0),MATCH($D$6&AK19,RegSplit!$B$2:$AN$2&RegSplit!$B$3:$AN$3,0))} -> 0 | BA23: {=INDEX(RegSplit!$B$4:$AN$6,MATCH(BA22,RegSplit!$A$4:$A$6,0),MATCH($D$6&AX19,RegSplit!$B$2:$AN$2&RegSplit!$B$3:$AN$3,0))} -> 1 | BB23: {=INDEX(RegSplit!$B$4:$AN$6,MATCH(BB22,RegSplit!$A$4:$A$6,0),MATCH($D$6&AX19,RegSplit!$B$2:$AN$2&RegSplit!$B$3:$AN$3,0))} -> 0 | BC23: {=INDEX(RegSplit!$B$4:$AN$6,MATCH(BC22,RegSplit!$A$4:$A$6,0),MATCH($D$6&AX19,RegSplit!$B$2:$AN$2&RegSplit!$B$3:$AN$3,0))} -> 0 | BN23: {=INDEX(RegSplit!$B$4:$AN$6,MATCH(BN22,RegSplit!$A$4:$A$6,0),MATCH($D$6&BK19,RegSplit!$B$2:$AN$2&RegSplit!$B$3:$AN$3,0))} -> 1 | BO23: {=INDEX(RegSplit!$B$4:$AN$6,MATCH(BO22,RegSplit!$A$4:$A$6,0),MATCH($D$6&BK19,RegSplit!$B$2:$AN$2&RegSplit!$B$3:$AN$3,0))} -> 0 | BP23: {=INDEX(RegSplit!$B$4:$AN$6,MATCH(BP22,RegSplit!$A$4:$A$6,0),MATCH($D$6&BK19,RegSplit!$B$2:$AN$2&RegSplit!$B$3:$AN$3,0))} -> 0
C24: TechName | D24: *TechDesc | E24: Comm-IN | F24: Comm-OUT | G24: STOCK~AZ1 | H24: STOCK~AZ2 | I24: STOCK~AZ3 | J24: STOCK~AZ1~2015 | K24: STOCK~AZ2~2015 | L24: STOCK~AZ3~2015 | M24: STOCK~AZ1~2019 | N24: STOCK~AZ2~2019 | O24: STOCK~AZ3~2019 | P24: STOCK~AZ1~2020 | Q24: STOCK~AZ2~2020 | R24: STOCK~AZ3~2020 | S24: STOCK~AZ1~2034 | T24: STOCK~AZ2~2034 | U24: STOCK~AZ3~2034 | V24: STOCK~0 | W24: EFF~AZ1 | X24: EFF~AZ2 | Y24: EFF~AZ3 | Z24: CAPUNIT | AA24: AFA | AB24: LIFE | AC24: Share-I~UP | AD24: Share-I~UP~2014 | AE24: Share-I~UP~0 | AM24: Fuel demand by energy service | AQ24: Energy service demand | AT24: Fuel demand (calculated) | AZ24: Fuel demand by energy service | BD24: Energy service demand | BG24: Fuel demand (calculated) | BM24: Fuel demand by energy service | BQ24: Energy service demand | BT24: Fuel demand (calculated)
C25: *Unit | G25: MW | H25: MW | J25: MW | K25: MW | M25: MW | N25: MW | P25: MW | Q25: MW | S25: MW | T25: MW | V25: Interpolation | W25: PJ/PJ | X25: PJ/PJ | Z25: KW/PJ | AB25: Year | AE25: Interpolation | AG25: 2010 | AH25: 2012 | AI25: 2014 | AL25: PJ | AM25: Demand base year DK | AN25: AZ1 | AO25: AZ2 | AP25: AZ3 | AQ25: AZ1 | AR25: AZ2 | AS25: AZ3 | AT25: AZ1 | AU25: AZ2 | AV25: AZ3 | AY25: PJ | AZ25: Demand DK | BA25: AZ1 | BB25: AZ2 | BC25: AZ3 | BD25: AZ1 | BE25: AZ2 | BF25: AZ3 | BG25: AZ1 | BH25: AZ2 | BI25: AZ3 | BL25: PJ | BM25: Demand base year DK | BN25: AZ1 | BO25: AZ2 | BP25: AZ3 | BQ25: AZ1 | BR25: AZ2 | BS25: AZ3 | BT25: AZ1 | BU25: AZ2 | BV25: AZ3
C26: =+IF(OFFSET(Processes!B7,$D$11,0)="*","*",OFFSET(Processes!D7,$D$11,0)) -> INDSDPHBNGAE1 | D26: =+OFFSET(Processes!E7,$D$11,0) -> Iron & Steel Heat Medium Temp. Boiler - Nat. Gas Existing 1 | E26: =+Processes!O7 -> INDSNG1,INDSNG2,INDNGA | F26: =+OFFSET(Processes!$M$12,$D$11,0) & Processes!P7 -> ISDPH | G26: =ROUNDUP(AN26/($Z26*$AA26)*G$21*W26,3) -> 12292.316 | H26: =ROUNDUP(AO26/($Z26*$AA26)*H$21*X26,3) -> 0 | I26: =ROUNDUP(AP26/($Z26*$AA26)*I$21*Y26,3) -> 0 | J26: =ROUNDUP(BA26/($Z26*$AA26)*J$21*W26,3) -> 11706.984 | K26: =ROUNDUP(BB26/($Z26*$AA26)*K$21*X26,3) -> 0 | L26: =ROUNDUP(BC26/($Z26*$AA26)*L$21*Y26,3) -> 0 | M26: =ROUNDUP(BN26/($Z26*$AA26)*M$21*W26,3) -> 11291.944 | N26: =ROUNDUP(BO26/($Z26*$AA26)*N$21*X26,3) -> 0 | O26: =ROUNDUP(BP26/($Z26*$AA26)*O$21*Y26,3) -> 0 | P26: =M26 -> 11291.944 | Q26: =N26 -> 0 | R26: =O26 -> 0 | S26: =IF($AB26=20,0,M26/5)*IF(M26=0,0,1) -> 0 | T26: =IF($AB26=20,0,N26/5)*IF(N26=0,0,1) -> 0 | U26: =IF($AB26=20,0,O26/5)*IF(O26=0,0,1) -> 0 | V26: 5 | W26: =I131 -> 0.98 | X26: =W26 -> 0.98 | Y26: =X26 -> 0.98 | Z26: =3.6*8760/1000000 -> 0.031536 | AA26: 0.5 | AB26: 20 | AG26: =((G26*Z26*AA26/W26)+(H26*Z26*AA26/X26))/$G$21 -> 197.58327 | AH26: =((J26*Z26*AA26/W26)+(K26*Z26*AA26/X26))/$J$21 -> 186.498 | AI26: =((M26*AA26*Z26/W26)+(N26*Z26*AA26/X26))/$M$21 -> 179.88621 | AK26: =F26 -> ISDPH | AL26: NGA | AM26: =(J77+I77)/1000 -> 197.58326 | AN26: =AM26*$AN$23 -> 197.58326 | AO26: =AM26*$AO$23 -> 0 | AP26: =AM26*$AP$23 -> 0 | AQ26: =AN26*$W26 -> 193.63159 | AR26: =AO26*$X26 -> 0 | AS26: =AP26*$Y26 -> 0 | AT26: =IFERROR(AQ26/W26,0) -> 197.58326 | AU26: =IFERROR(AR26/X26,0) -> 0 | AV26: =IFERROR(AS26/Y26,0) -> 0 | AX26: =AK26 -> ISDPH | AY26: NGA | AZ26: =(J97+I97)/1000 -> 186.498 | BA26: =AZ26*$AN$23 -> 186.498 | BB26: =AZ26*$BB$23 -> 0 | BC26: =AZ26*$BC$23 -> 0 | BD26: =IFERROR(J26*$Z26*AA26/J$21,0) -> 182.76804 | BE26: =IFERROR(K26*$Z26*AA26/K$21,0) -> 0 | BF26: =IFERROR(L26*$Z26*AA26/L$21,0) -> 0 | BG26: =IFERROR(BD26/W26,0) -> 186.498 | BH26: =IFERROR(BE26/X26,0) -> 0 | BI26: =IFERROR(BF26/Y26,0) -> 0 | BK26: =AK26 -> ISDPH | BL26: NGA | BM26: =(J117+I117)/1000 -> 179.88621 | BN26: =BM26*$AN$23 -> 179.88621 | BO26: =BM26*$BB$23 -> 0 | BP26: =BM26*$BC$23 -> 0 | BQ26: =IFERROR(M26*$Z26*$AA26/M$21,0) -> 176.28849 | BR26: =IFERROR(N26*$Z26*$AA26/N$21,0) -> 0 | BS26: =IFERROR(O26*$Z26*$AA26/O$21,0) -> 0 | BT26: =IFERROR(BQ26/W26,0) -> 179.88621 | BU26: =IFERROR(BR26/X26,0) -> 0 | BV26: =IFERROR(BS26/Y26,0) -> 0
